Workbook

Sheet Jan
A1: =Summen!B1 -> Alta Engineering AG | F1: Monatsblatt | H1: Name: | J1: =Summen!B3 -> Michael Küng | N1: Monat: | P1: =Summen!B27 -> 46023 | S1: Anstellung : | U1: =Summen!B5 -> 1 | W1: Blatt Nr. | X1: 1
C2: Ferien: | E2: =Summen!B18 -> 10.8 | F2: Bezogen: | H2: 0 | I2: Rest: | J2: =E2-H2 -> 10.8 | T2: Stundenübertrag Vormonat : | U2: =Summen!B14 -> 0 | V2: Spesen
A3: Projekte | C3: Alta Engineering | L3: krank | M3: Reisezeit | N3: CAD | O3: Ausbildung | P3: Büro | Q3: Ferien | R3: Soll | S3: Ist | T3: +/- | U3: Stand | V3: Fr. | W3: Km | X3: Summe | Y3: Start [hh:mm] | Z3: Stop [hh:mm] | AA3: Start [hh:mm] | AB3: Stop [hh:mm] | AC3: Start [hh:mm] | AD3: Stop [hh:mm] | AE3: Start [hh:mm] | AF3: Stop [hh:mm] | AG3: Ist-Zeit [hh:mm] | AH3: Ist-Zeit [hh] | AI3: Ist-Zeit [.hh] | AJ3: Ist-Zeit [h.h] | AL3: Aufteilung - Istzeit
A4: =P1 -> 46023 | B4: =IFERROR(VLOOKUP(A4, Feiertage!$B:$C, 2, 0), IF(OR(WEEKDAY(A4,2)=6, WEEKDAY(A4,2)=7), Feiertage!$C$23, "")) -> * * * * * * * * Neujahr * * * * * * * * * * * * * * * * * * * * * * * * * * * * * * * * * * * * * * * * * * * * * * * * * * * * | R4: =IF(OR(WEEKDAY(A4,2)=6,WEEKDAY(A4,2)=7),0,IFERROR(IF(VLOOKUP(A4,Feiertage!$B:$D,3,0)="ja",0,Summen!$B$9),Summen!$B$9)) -> 0 | S4: =SUM(C4:Q4) -> 0 | T4: =S4-R4 -> 0 | U4: =U2+T4 -> 0 | X4: =V4+W4*Summen!$B$44 -> 0 | AG4: =(Z4-Y4)+(AB4-AA4)+(AD4-AC4)+(AF4-AE4) -> 0 | AH4: =HOUR(AG4) -> 0 | AI4: =MINUTE(AG4)/60 -> 0 | AJ4: =AH4+AI4 -> 0 | AL4: =SUM(C4:Q4)-AJ4 -> 0
A5: =A4+1 -> 46024 | B5: =IFERROR(VLOOKUP(A5, Feiertage!$B:$C, 2, 0), IF(OR(WEEKDAY(A5,2)=6, WEEKDAY(A5,2)=7), Feiertage!$C$23, "")) | R5: 0 | S5: =SUM(C5:Q5) -> 0 | T5: =S5-R5 -> 0 | U5: =U4+T5 -> 0 | X5: =V5+W5*Summen!$B$44 -> 0 | AG5: =(Z5-Y5)+(AB5-AA5)+(AD5-AC5)+(AF5-AE5) -> 0 | AH5: =HOUR(AG5) -> 0 | AI5: =MINUTE(AG5)/60 -> 0 | AJ5: =AH5+AI5 -> 0 | AL5: =SUM(C5:Q5)-AJ5 -> 0
A6: =A5+1 -> 46025 | B6: =IFERROR(VLOOKUP(A6, Feiertage!$B:$C, 2, 0), IF(OR(WEEKDAY(A6,2)=6, WEEKDAY(A6,2)=7), Feiertage!$C$23, "")) -> * * * * * * * * Wochenende * * * * * * * * * * * * * * * * * * * * * * * * * * * * * * * * * * * * * * * * * * * * * * * * | R6: =IF(OR(WEEKDAY(A6,2)=6,WEEKDAY(A6,2)=7),0,IFERROR(IF(VLOOKUP(A6,Feiertage!$B:$D,3,0)="ja",0,Summen!$B$9),Summen!$B$9)) -> 0 | S6: =SUM(C6:Q6) -> 0 | T6: =S6-R6 -> 0 | U6: =U5+T6 -> 0 | X6: =V6+W6*Summen!$B$44 -> 0 | AG6: =(Z6-Y6)+(AB6-AA6)+(AD6-AC6)+(AF6-AE6) -> 0 | AH6: =HOUR(AG6) -> 0 | AI6: =MINUTE(AG6)/60 -> 0 | AJ6: =AH6+AI6 -> 0 | AL6: =SUM(C6:Q6)-AJ6 -> 0
A7: =A6+1 -> 46026 | B7: =IFERROR(VLOOKUP(A7, Feiertage!$B:$C, 2, 0), IF(OR(WEEKDAY(A7,2)=6, WEEKDAY(A7,2)=7), Feiertage!$C$23, "")) -> * * * * * * * * Wochenende * * * * * * * * * * * * * * * * * * * * * * * * * * * * * * * * * * * * * * * * * * * * * * * * | R7: =IF(OR(WEEKDAY(A7,2)=6,WEEKDAY(A7,2)=7),0,IFERROR(IF(VLOOKUP(A7,Feiertage!$B:$D,3,0)="ja",0,Summen!$B$9),Summen!$B$9)) -> 0 | S7: =SUM(C7:Q7) -> 0 | T7: =S7-R7 -> 0 | U7: =U6+T7 -> 0 | X7: =V7+W7*Summen!$B$44 -> 0 | AG7: =(Z7-Y7)+(AB7-AA7)+(AD7-AC7)+(AF7-AE7) -> 0 | AH7: =HOUR(AG7) -> 0 | AI7: =MINUTE(AG7)/60 -> 0 | AJ7: =AH7+AI7 -> 0 | AL7: =SUM(C7:Q7)-AJ7 -> 0
A8: =A7+1 -> 46027 | B8: =IFERROR(VLOOKUP(A8, Feiertage!$B:$C, 2, 0), IF(OR(WEEKDAY(A8,2)=6, WEEKDAY(A8,2)=7), Feiertage!$C$23, "")) | R8: 0 | S8: =SUM(C8:Q8) -> 0 | T8: =S8-R8 -> 0 | U8: =U7+T8 -> 0 | X8: =V8+W8*Summen!$B$44 -> 0 | AG8: =(Z8-Y8)+(AB8-AA8)+(AD8-AC8)+(AF8-AE8) -> 0 | AH8: =HOUR(AG8) -> 0 | AI8: =MINUTE(AG8)/60 -> 0 | AJ8: =AH8+AI8 -> 0 | AL8: =SUM(C8:Q8)-AJ8 -> 0
A9: =A8+1 -> 46028 | B9: =IFERROR(VLOOKUP(A9, Feiertage!$B:$C, 2, 0), IF(OR(WEEKDAY(A9,2)=6, WEEKDAY(A9,2)=7), Feiertage!$C$23, "")) | R9: 0 | S9: =SUM(C9:Q9) -> 0 | T9: =S9-R9 -> 0 | U9: =U8+T9 -> 0 | X9: =V9+W9*Summen!$B$44 -> 0 | AG9: =(Z9-Y9)+(AB9-AA9)+(AD9-AC9)+(AF9-AE9) -> 0 | AH9: =HOUR(AG9) -> 0 | AI9: =MINUTE(AG9)/60 -> 0 | AJ9: =AH9+AI9 -> 0 | AL9: =SUM(C9:Q9)-AJ9 -> 0
A10: =A9+1 -> 46029 | B10: =IFERROR(VLOOKUP(A10, Feiertage!$B:$C, 2, 0), IF(OR(WEEKDAY(A10,2)=6, WEEKDAY(A10,2)=7), Feiertage!$C$23, "")) | R10: 0 | S10: =SUM(C10:Q10) -> 0 | T10: =S10-R10 -> 0 | U10: =U9+T10 -> 0 | X10: =V10+W10*Summen!$B$44 -> 0 | AG10: =(Z10-Y10)+(AB10-AA10)+(AD10-AC10)+(AF10-AE10) -> 0 | AH10: =HOUR(AG10) -> 0 | AI10: =MINUTE(AG10)/60 -> 0 | AJ10: =AH10+AI10 -> 0 | AL10: =SUM(C10:Q10)-AJ10 -> 0
A11: =A10+1 -> 46030 | B11: =IFERROR(VLOOKUP(A11, Feiertage!$B:$C, 2, 0), IF(OR(WEEKDAY(A11,2)=6, WEEKDAY(A11,2)=7), Feiertage!$C$23, "")) | R11: 0 | S11: =SUM(C11:Q11) -> 0 | T11: =S11-R11 -> 0 | U11: =U10+T11 -> 0 | X11: =V11+W11*Summen!$B$44 -> 0 | AG11: =(Z11-Y11)+(AB11-AA11)+(AD11-AC11)+(AF11-AE11) -> 0 | AH11: =HOUR(AG11) -> 0 | AI11: =MINUTE(AG11)/60 -> 0 | AJ11: =AH11+AI11 -> 0 | AL11: =SUM(C11:Q11)-AJ11 -> 0
A12: =A11+1 -> 46031 | B12: =IFERROR(VLOOKUP(A12, Feiertage!$B:$C, 2, 0), IF(OR(WEEKDAY(A12,2)=6, WEEKDAY(A12,2)=7), Feiertage!$C$23, "")) | R12: 0 | S12: =SUM(C12:Q12) -> 0 | T12: =S12-R12 -> 0 | U12: =U11+T12 -> 0 | X12: =V12+W12*Summen!$B$44 -> 0 | AG12: =(Z12-Y12)+(AB12-AA12)+(AD12-AC12)+(AF12-AE12) -> 0 | AH12: =HOUR(AG12) -> 0 | AI12: =MINUTE(AG12)/60 -> 0 | AJ12: =AH12+AI12 -> 0 | AL12: =SUM(C12:Q12)-AJ12 -> 0
A13: =A12+1 -> 46032 | B13: =IFERROR(VLOOKUP(A13, Feiertage!$B:$C, 2, 0), IF(OR(WEEKDAY(A13,2)=6, WEEKDAY(A13,2)=7), Feiertage!$C$23, "")) -> * * * * * * * * Wochenende * * * * * * * * * * * * * * * * * * * * * * * * * * * * * * * * * * * * * * * * * * * * * * * * | R13: =IF(OR(WEEKDAY(A13,2)=6,WEEKDAY(A13,2)=7),0,IFERROR(IF(VLOOKUP(A13,Feiertage!$B:$D,3,0)="ja",0,Summen!$B$9),Summen!$B$9)) -> 0 | S13: =SUM(C13:Q13) -> 0 | T13: =S13-R13 -> 0 | U13: =U12+T13 -> 0 | X13: =V13+W13*Summen!$B$44 -> 0 | AG13: =(Z13-Y13)+(AB13-AA13)+(AD13-AC13)+(AF13-AE13) -> 0 | AH13: =HOUR(AG13) -> 0 | AI13: =MINUTE(AG13)/60 -> 0 | AJ13: =AH13+AI13 -> 0 | AL13: =SUM(C13:Q13)-AJ13 -> 0
A14: =A13+1 -> 46033 | B14: =IFERROR(VLOOKUP(A14, Feiertage!$B:$C, 2, 0), IF(OR(WEEKDAY(A14,2)=6, WEEKDAY(A14,2)=7), Feiertage!$C$23, "")) -> * * * * * * * * Wochenende * * * * * * * * * * * * * * * * * * * * * * * * * * * * * * * * * * * * * * * * * * * * * * * * | R14: =IF(OR(WEEKDAY(A14,2)=6,WEEKDAY(A14,2)=7),0,IFERROR(IF(VLOOKUP(A14,Feiertage!$B:$D,3,0)="ja",0,Summen!$B$9),Summen!$B$9)) -> 0 | S14: =SUM(C14:Q14) -> 0 | T14: =S14-R14 -> 0 | U14: =U13+T14 -> 0 | X14: =V14+W14*Summen!$B$44 -> 0 | AG14: =(Z14-Y14)+(AB14-AA14)+(AD14-AC14)+(AF14-AE14) -> 0 | AH14: =HOUR(AG14) -> 0 | AI14: =MINUTE(AG14)/60 -> 0 | AJ14: =AH14+AI14 -> 0 | AL14: =SUM(C14:Q14)-AJ14 -> 0
A15: =A14+1 -> 46034 | B15: =IFERROR(VLOOKUP(A15, Feiertage!$B:$C, 2, 0), IF(OR(WEEKDAY(A15,2)=6, WEEKDAY(A15,2)=7), Feiertage!$C$23, "")) | R15: 0 | S15: =SUM(C15:Q15) -> 0 | T15: =S15-R15 -> 0 | U15: =U14+T15 -> 0 | X15: =V15+W15*Summen!$B$44 -> 0 | AG15: =(Z15-Y15)+(AB15-AA15)+(AD15-AC15)+(AF15-AE15) -> 0 | AH15: =HOUR(AG15) -> 0 | AI15: =MINUTE(AG15)/60 -> 0 | AJ15: =AH15+AI15 -> 0 | AL15: =SUM(C15:Q15)-AJ15 -> 0
A16: =A15+1 -> 46035 | B16: =IFERROR(VLOOKUP(A16, Feiertage!$B:$C, 2, 0), IF(OR(WEEKDAY(A16,2)=6, WEEKDAY(A16,2)=7), Feiertage!$C$23, "")) | R16: 0 | S16: =SUM(C16:Q16) -> 0 | T16: =S16-R16 -> 0 | U16: =U15+T16 -> 0 | X16: =V16+W16*Summen!$B$44 -> 0 | AG16: =(Z16-Y16)+(AB16-AA16)+(AD16-AC16)+(AF16-AE16) -> 0 | AH16: =HOUR(AG16) -> 0 | AI16: =MINUTE(AG16)/60 -> 0 | AJ16: =AH16+AI16 -> 0 | AL16: =SUM(C16:Q16)-AJ16 -> 0
A17: =A16+1 -> 46036 | B17: =IFERROR(VLOOKUP(A17, Feiertage!$B:$C, 2, 0), IF(OR(WEEKDAY(A17,2)=6, WEEKDAY(A17,2)=7), Feiertage!$C$23, "")) | R17: 0 | S17: =SUM(C17:Q17) -> 0 | T17: =S17-R17 -> 0 | U17: =U16+T17 -> 0 | X17: =V17+W17*Summen!$B$44 -> 0 | AG17: =(Z17-Y17)+(AB17-AA17)+(AD17-AC17)+(AF17-AE17) -> 0 | AH17: =HOUR(AG17) -> 0 | AI17: =MINUTE(AG17)/60 -> 0 | AJ17: =AH17+AI17 -> 0 | AL17: =SUM(C17:Q17)-AJ17 -> 0
A18: =A17+1 -> 46037 | B18: =IFERROR(VLOOKUP(A18, Feiertage!$B:$C, 2, 0), IF(OR(WEEKDAY(A18,2)=6, WEEKDAY(A18,2)=7), Feiertage!$C$23, "")) | R18: 0 | S18: =SUM(C18:Q18) -> 0 | T18: =S18-R18 -> 0 | U18: =U17+T18 -> 0 | X18: =V18+W18*Summen!$B$44 -> 0 | AG18: =(Z18-Y18)+(AB18-AA18)+(AD18-AC18)+(AF18-AE18) -> 0 | AH18: =HOUR(AG18) -> 0 | AI18: =MINUTE(AG18)/60 -> 0 | AJ18: =AH18+AI18 -> 0 | AL18: =SUM(C18:Q18)-AJ18 -> 0
A19: =A18+1 -> 46038 | B19: =IFERROR(VLOOKUP(A19, Feiertage!$B:$C, 2, 0), IF(OR(WEEKDAY(A19,2)=6, WEEKDAY(A19,2)=7), Feiertage!$C$23, "")) | R19: 0 | S19: =SUM(C19:Q19) -> 0 | T19: =S19-R19 -> 0 | U19: =U18+T19 -> 0 | X19: =V19+W19*Summen!$B$44 -> 0 | AG19: =(Z19-Y19)+(AB19-AA19)+(AD19-AC19)+(AF19-AE19) -> 0 | AH19: =HOUR(AG19) -> 0 | AI19: =MINUTE(AG19)/60 -> 0 | AJ19: =AH19+AI19 -> 0 | AL19: =SUM(C19:Q19)-AJ19 -> 0
A20: =A19+1 -> 46039 | B20: =IFERROR(VLOOKUP(A20, Feiertage!$B:$C, 2, 0), IF(OR(WEEKDAY(A20,2)=6, WEEKDAY(A20,2)=7), Feiertage!$C$23, "")) -> * * * * * * * * Wochenende * * * * * * * * * * * * * * * * * * * * * * * * * * * * * * * * * * * * * * * * * * * * * * * * | R20: =IF(OR(WEEKDAY(A20,2)=6,WEEKDAY(A20,2)=7),0,IFERROR(IF(VLOOKUP(A20,Feiertage!$B:$D,3,0)="ja",0,Summen!$B$9),Summen!$B$9)) -> 0 | S20: =SUM(C20:Q20) -> 0 | T20: =S20-R20 -> 0 | U20: =U19+T20 -> 0 | X20: =V20+W20*Summen!$B$44 -> 0 | AG20: =(Z20-Y20)+(AB20-AA20)+(AD20-AC20)+(AF20-AE20) -> 0 | AH20: =HOUR(AG20) -> 0 | AI20: =MINUTE(AG20)/60 -> 0 | AJ20: =AH20+AI20 -> 0 | AL20: =SUM(C20:Q20)-AJ20 -> 0
A21: =A20+1 -> 46040 | B21: =IFERROR(VLOOKUP(A21, Feiertage!$B:$C, 2, 0), IF(OR(WEEKDAY(A21,2)=6, WEEKDAY(A21,2)=7), Feiertage!$C$23, "")) -> * * * * * * * * Wochenende * * * * * * * * * * * * * * * * * * * * * * * * * * * * * * * * * * * * * * * * * * * * * * * * | R21: =IF(OR(WEEKDAY(A21,2)=6,WEEKDAY(A21,2)=7),0,IFERROR(IF(VLOOKUP(A21,Feiertage!$B:$D,3,0)="ja",0,Summen!$B$9),Summen!$B$9)) -> 0 | S21: =SUM(C21:Q21) -> 0 | T21: =S21-R21 -> 0 | U21: =U20+T21 -> 0 | X21: =V21+W21*Summen!$B$44 -> 0 | AG21: =(Z21-Y21)+(AB21-AA21)+(AD21-AC21)+(AF21-AE21) -> 0 | AH21: =HOUR(AG21) -> 0 | AI21: =MINUTE(AG21)/60 -> 0 | AJ21: =AH21+AI21 -> 0 | AL21: =SUM(C21:Q21)-AJ21 -> 0
A22: =A21+1 -> 46041 | B22: =IFERROR(VLOOKUP(A22, Feiertage!$B:$C, 2, 0), IF(OR(WEEKDAY(A22,2)=6, WEEKDAY(A22,2)=7), Feiertage!$C$23, "")) | R22: 0 | S22: =SUM(C22:Q22) -> 0 | T22: =S22-R22 -> 0 | U22: =U21+T22 -> 0 | X22: =V22+W22*Summen!$B$44 -> 0 | AG22: =(Z22-Y22)+(AB22-AA22)+(AD22-AC22)+(AF22-AE22) -> 0 | AH22: =HOUR(AG22) -> 0 | AI22: =MINUTE(AG22)/60 -> 0 | AJ22: =AH22+AI22 -> 0 | AL22: =SUM(C22:Q22)-AJ22 -> 0
A23: =A22+1 -> 46042 | B23: =IFERROR(VLOOKUP(A23, Feiertage!$B:$C, 2, 0), IF(OR(WEEKDAY(A23,2)=6, WEEKDAY(A23,2)=7), Feiertage!$C$23, "")) | R23: 0 | S23: =SUM(C23:Q23) -> 0 | T23: =S23-R23 -> 0 | U23: =U22+T23 -> 0 | X23: =V23+W23*Summen!$B$44 -> 0 | AG23: =(Z23-Y23)+(AB23-AA23)+(AD23-AC23)+(AF23-AE23) -> 0 | AH23: =HOUR(AG23) -> 0 | AI23: =MINUTE(AG23)/60 -> 0 | AJ23: =AH23+AI23 -> 0 | AL23: =SUM(C23:Q23)-AJ23 -> 0
A24: =A23+1 -> 46043 | B24: =IFERROR(VLOOKUP(A24, Feiertage!$B:$C, 2, 0), IF(OR(WEEKDAY(A24,2)=6, WEEKDAY(A24,2)=7), Feiertage!$C$23, "")) | R24: 0 | S24: =SUM(C24:Q24) -> 0 | T24: =S24-R24 -> 0 | U24: =U23+T24 -> 0 | X24: =V24+W24*Summen!$B$44 -> 0 | AG24: =(Z24-Y24)+(AB24-AA24)+(AD24-AC24)+(AF24-AE24) -> 0 | AH24: =HOUR(AG24) -> 0 | AI24: =MINUTE(AG24)/60 -> 0 | AJ24: =AH24+AI24 -> 0 | AL24: =SUM(C24:Q24)-AJ24 -> 0
A25: =A24+1 -> 46044 | B25: =IFERROR(VLOOKUP(A25, Feiertage!$B:$C, 2, 0), IF(OR(WEEKDAY(A25,2)=6, WEEKDAY(A25,2)=7), Feiertage!$C$23, "")) | R25: 0 | S25: =SUM(C25:Q25) -> 0 | T25: =S25-R25 -> 0 | U25: =U24+T25 -> 0 | X25: =V25+W25*Summen!$B$44 -> 0 | AG25: =(Z25-Y25)+(AB25-AA25)+(AD25-AC25)+(AF25-AE25) -> 0 | AH25: =HOUR(AG25) -> 0 | AI25: =MINUTE(AG25)/60 -> 0 | AJ25: =AH25+AI25 -> 0 | AL25: =SUM(C25:Q25)-AJ25 -> 0
A26: =A25+1 -> 46045 | B26: =IFERROR(VLOOKUP(A26, Feiertage!$B:$C, 2, 0), IF(OR(WEEKDAY(A26,2)=6, WEEKDAY(A26,2)=7), Feiertage!$C$23, "")) | R26: 0 | S26: =SUM(C26:Q26) -> 0 | T26: =S26-R26 -> 0 | U26: =U25+T26 -> 0 | X26: =V26+W26*Summen!$B$44 -> 0 | AG26: =(Z26-Y26)+(AB26-AA26)+(AD26-AC26)+(AF26-AE26) -> 0 | AH26: =HOUR(AG26) -> 0 | AI26: =MINUTE(AG26)/60 -> 0 | AJ26: =AH26+AI26 -> 0 | AL26: =SUM(C26:Q26)-AJ26 -> 0
A27: =A26+1 -> 46046 | B27: =IFERROR(VLOOKUP(A27, Feiertage!$B:$C, 2, 0), IF(OR(WEEKDAY(A27,2)=6, WEEKDAY(A27,2)=7), Feiertage!$C$23, "")) -> * * * * * * * * Wochenende * * * * * * * * * * * * * * * * * * * * * * * * * * * * * * * * * * * * * * * * * * * * * * * * | R27: =IF(OR(WEEKDAY(A27,2)=6,WEEKDAY(A27,2)=7),0,IFERROR(IF(VLOOKUP(A27,Feiertage!$B:$D,3,0)="ja",0,Summen!$B$9),Summen!$B$9)) -> 0 | S27: =SUM(C27:Q27) -> 0 | T27: =S27-R27 -> 0 | U27: =U26+T27 -> 0 | X27: =V27+W27*Summen!$B$44 -> 0 | AG27: =(Z27-Y27)+(AB27-AA27)+(AD27-AC27)+(AF27-AE27) -> 0 | AH27: =HOUR(AG27) -> 0 | AI27: =MINUTE(AG27)/60 -> 0 | AJ27: =AH27+AI27 -> 0 | AL27: =SUM(C27:Q27)-AJ27 -> 0
A28: =A27+1 -> 46047 | B28: =IFERROR(VLOOKUP(A28, Feiertage!$B:$C, 2, 0), IF(OR(WEEKDAY(A28,2)=6, WEEKDAY(A28,2)=7), Feiertage!$C$23, "")) -> * * * * * * * * Wochenende * * * * * * * * * * * * * * * * * * * * * * * * * * * * * * * * * * * * * * * * * * * * * * * * | R28: =IF(OR(WEEKDAY(A28,2)=6,WEEKDAY(A28,2)=7),0,IFERROR(IF(VLOOKUP(A28,Feiertage!$B:$D,3,0)="ja",0,Summen!$B$9),Summen!$B$9)) -> 0 | S28: =SUM(C28:Q28) -> 0 | T28: =S28-R28 -> 0 | U28: =U27+T28 -> 0 | X28: =V28+W28*Summen!$B$44 -> 0 | AG28: =(Z28-Y28)+(AB28-AA28)+(AD28-AC28)+(AF28-AE28) -> 0 | AH28: =HOUR(AG28) -> 0 | AI28: =MINUTE(AG28)/60 -> 0 | AJ28: =AH28+AI28 -> 0 | AL28: =SUM(C28:Q28)-AJ28 -> 0
A29: =A28+1 -> 46048 | B29: =IFERROR(VLOOKUP(A29, Feiertage!$B:$C, 2, 0), IF(OR(WEEKDAY(A29,2)=6, WEEKDAY(A29,2)=7), Feiertage!$C$23, "")) | R29: 0 | S29: =SUM(C29:Q29) -> 0 | T29: =S29-R29 -> 0 | U29: =U28+T29 -> 0 | X29: =V29+W29*Summen!$B$44 -> 0 | AG29: =(Z29-Y29)+(AB29-AA29)+(AD29-AC29)+(AF29-AE29) -> 0 | AH29: =HOUR(AG29) -> 0 | AI29: =MINUTE(AG29)/60 -> 0 | AJ29: =AH29+AI29 -> 0 | AL29: =SUM(C29:Q29)-AJ29 -> 0
A30: =A29+1 -> 46049 | B30: =IFERROR(VLOOKUP(A30, Feiertage!$B:$C, 2, 0), IF(OR(WEEKDAY(A30,2)=6, WEEKDAY(A30,2)=7), Feiertage!$C$23, "")) | R30: 0 | S30: =SUM(C30:Q30) -> 0 | T30: =S30-R30 -> 0 | U30: =U29+T30 -> 0 | X30: =V30+W30*Summen!$B$44 -> 0 | AG30: =(Z30-Y30)+(AB30-AA30)+(AD30-AC30)+(AF30-AE30) -> 0 | AH30: =HOUR(AG30) -> 0 | AI30: =MINUTE(AG30)/60 -> 0 | AJ30: =AH30+AI30 -> 0 | AL30: =SUM(C30:Q30)-AJ30 -> 0
A31: =A30+1 -> 46050 | B31: =IFERROR(VLOOKUP(A31, Feiertage!$B:$C, 2, 0), IF(OR(WEEKDAY(A31,2)=6, WEEKDAY(A31,2)=7), Feiertage!$C$23, "")) | R31: 0 | S31: =SUM(C31:Q31) -> 0 | T31: =S31-R31 -> 0 | U31: =U30+T31 -> 0 | X31: =V31+W31*Summen!$B$44 -> 0 | AG31: =(Z31-Y31)+(AB31-AA31)+(AD31-AC31)+(AF31-AE31) -> 0 | AH31: =HOUR(AG31) -> 0 | AI31: =MINUTE(AG31)/60 -> 0 | AJ31: =AH31+AI31 -> 0 | AL31: =SUM(C31:Q31)-AJ31 -> 0
A32: =A31+1 -> 46051 | B32: =IFERROR(VLOOKUP(A32, Feiertage!$B:$C, 2, 0), IF(OR(WEEKDAY(A32,2)=6, WEEKDAY(A32,2)=7), Feiertage!$C$23, "")) | R32: 0 | S32: =SUM(C32:Q32) -> 0 | T32: =S32-R32 -> 0 | U32: =U31+T32 -> 0 | X32: =V32+W32*Summen!$B$44 -> 0 | AG32: =(Z32-Y32)+(AB32-AA32)+(AD32-AC32)+(AF32-AE32) -> 0 | AH32: =HOUR(AG32) -> 0 | AI32: =MINUTE(AG32)/60 -> 0 | AJ32: =AH32+AI32 -> 0 | AL32: =SUM(C32:Q32)-AJ32 -> 0
A33: =A32+1 -> 46052 | B33: =IFERROR(VLOOKUP(A33, Feiertage!$B:$C, 2, 0), IF(OR(WEEKDAY(A33,2)=6, WEEKDAY(A33,2)=7), Feiertage!$C$23, "")) | R33: 0 | S33: =SUM(C33:Q33) -> 0 | T33: =S33-R33 -> 0 | U33: =U32+T33 -> 0 | X33: =V33+W33*Summen!$B$44 -> 0 | AG33: =(Z33-Y33)+(AB33-AA33)+(AD33-AC33)+(AF33-AE33) -> 0 | AH33: =HOUR(AG33) -> 0 | AI33: =MINUTE(AG33)/60 -> 0 | AJ33: =AH33+AI33 -> 0 | AL33: =SUM(C33:Q33)-AJ33 -> 0
A34: =A33+1 -> 46053 | B34: =IFERROR(VLOOKUP(A34, Feiertage!$B:$C, 2, 0), IF(OR(WEEKDAY(A34,2)=6, WEEKDAY(A34,2)=7), Feiertage!$C$23, "")) -> * * * * * * * * Wochenende * * * * * * * * * * * * * * * * * * * * * * * * * * * * * * * * * * * * * * * * * * * * * * * * | R34: =IF(OR(WEEKDAY(A34,2)=6,WEEKDAY(A34,2)=7),0,IFERROR(IF(VLOOKUP(A34,Feiertage!$B:$D,3,0)="ja",0,Summen!$B$9),Summen!$B$9)) -> 0 | S34: =SUM(C34:Q34) -> 0 | T34: =S34-R34 -> 0 | U34: =U33+T34 -> 0 | X34: =V34+W34*Summen!$B$44 -> 0 | AG34: =(Z34-Y34)+(AB34-AA34)+(AD34-AC34)+(AF34-AE34) -> 0 | AH34: =HOUR(AG34) -> 0 | AI34: =MINUTE(AG34)/60 -> 0 | AJ34: =AH34+AI34 -> 0 | AL34: =SUM(C34:Q34)-AJ34 -> 0
A35: Total | C35: =SUM(C4:C34) -> 0 | D35: =SUM(D4:D34) -> 0 | E35: =SUM(E4:E34) -> 0 | F35: =SUM(F4:F34) -> 0 | G35: =SUM(G4:G34) -> 0 | H35: =SUM(H4:H34) -> 0 | I35: =SUM(I4:I34) -> 0 | J35: =SUM(J4:J34) -> 0 | ... T35: =SUM(T4:T34) -> 0 | U35: =U34 -> 0 | V35: =SUM(V4:V34) -> 0 | W35: =SUM(W4:W34)*Summen!$B$44 -> 0 | X35: =V35+W35 -> 0 | AJ35: =SUM(AJ4:AJ34) -> 0 | AL35: =SUM(C35:Q35)-AJ35 -> 0

Sheet Feb
A1: =Summen!B1 -> Alta Engineering AG | F1: Monatsblatt | H1: Name: | J1: =Summen!B3 -> Michael Küng | N1: Monat: | P1: =Jan!P1+31 -> 46054 | S1: Anstellung : | U1: =Summen!B5 -> 1 | W1: Blatt Nr. | X1: =Jan!X1+1 -> 2
C2: Ferien: | E2: =Summen!B18 -> 10.8 | F2: Bezogen: | H2: =Jan!H2+(Jan!Q35/Summen!B9) -> 0 | I2: Rest: | J2: =E2-H2 -> 10.8 | T2: Stundenübertrag Vormonat : | U2: =Jan!U35 -> 0 | V2: Spesen
A3: Projekte | C3: Pfisterer AG | D3: Alta Eng. | L3: krank | M3: Reisezeit | N3: CAD | O3: Ausbildung | P3: Büro | Q3: Ferien | R3: Soll | S3: Ist | T3: +/- | U3: Stand | V3: Fr. | W3: Km | X3: Summe | Y3: Start [hh:mm] | Z3: Stop [hh:mm] | AA3: Start [hh:mm] | AB3: Stop [hh:mm] | AC3: Start [hh:mm] | AD3: Stop [hh:mm] | AE3: Start [hh:mm] | AF3: Stop [hh:mm] | AG3: Ist-Zeit [hh:mm] | AH3: Ist-Zeit [hh] | AI3: Ist-Zeit [.hh] | AJ3: Ist-Zeit [h.h] | AL3: Aufteilung - Istzeit
A4: =P1 -> 46054 | B4: =IFERROR(VLOOKUP(A4, Feiertage!$B:$C, 2, 0), IF(OR(WEEKDAY(A4,2)=6, WEEKDAY(A4,2)=7), Feiertage!$C$23, "")) -> * * * * * * * * Wochenende * * * * * * * * * * * * * * * * * * * * * * * * * * * * * * * * * * * * * * * * * * * * * * * * | R4: =IF(OR(WEEKDAY(A4,2)=6,WEEKDAY(A4,2)=7),0,IFERROR(IF(VLOOKUP(A4,Feiertage!$B:$D,3,0)="ja",0,Summen!$B$9),Summen!$B$9)) -> 0 | S4: =SUM(C4:Q4) -> 0 | T4: =S4-R4 -> 0 | U4: =U2+T4 -> 0 | X4: =V4+W4*Summen!$B$44 -> 0 | AG4: =(Z4-Y4)+(AB4-AA4)+(AD4-AC4)+(AF4-AE4) -> 0 | AH4: =HOUR(AG4) -> 0 | AI4: =MINUTE(AG4)/60 -> 0 | AJ4: =AH4+AI4 -> 0 | AL4: =SUM(C4:Q4)-AJ4 -> 0
A5: =A4+1 -> 46055 | B5: =IFERROR(VLOOKUP(A5, Feiertage!$B:$C, 2, 0), IF(OR(WEEKDAY(A5,2)=6, WEEKDAY(A5,2)=7), Feiertage!$C$23, "")) | R5: 0 | S5: =SUM(C5:Q5) -> 0 | T5: =S5-R5 -> 0 | U5: =U4+T5 -> 0 | X5: =V5+W5*Summen!$B$44 -> 0 | AG5: =(Z5-Y5)+(AB5-AA5)+(AD5-AC5)+(AF5-AE5) -> 0 | AH5: =HOUR(AG5) -> 0 | AI5: =MINUTE(AG5)/60 -> 0 | AJ5: =AH5+AI5 -> 0 | AL5: =SUM(C5:Q5)-AJ5 -> 0
A6: =A5+1 -> 46056 | B6: =IFERROR(VLOOKUP(A6, Feiertage!$B:$C, 2, 0), IF(OR(WEEKDAY(A6,2)=6, WEEKDAY(A6,2)=7), Feiertage!$C$23, "")) | R6: 0 | S6: =SUM(C6:Q6) -> 0 | T6: =S6-R6 -> 0 | U6: =U5+T6 -> 0 | X6: =V6+W6*Summen!$B$44 -> 0 | AG6: =(Z6-Y6)+(AB6-AA6)+(AD6-AC6)+(AF6-AE6) -> 0 | AH6: =HOUR(AG6) -> 0 | AI6: =MINUTE(AG6)/60 -> 0 | AJ6: =AH6+AI6 -> 0 | AL6: =SUM(C6:Q6)-AJ6 -> 0
A7: =A6+1 -> 46057 | B7: =IFERROR(VLOOKUP(A7, Feiertage!$B:$C, 2, 0), IF(OR(WEEKDAY(A7,2)=6, WEEKDAY(A7,2)=7), Feiertage!$C$23, "")) | R7: 0 | S7: =SUM(C7:Q7) -> 0 | T7: =S7-R7 -> 0 | U7: =U6+T7 -> 0 | X7: =V7+W7*Summen!$B$44 -> 0 | AG7: =(Z7-Y7)+(AB7-AA7)+(AD7-AC7)+(AF7-AE7) -> 0 | AH7: =HOUR(AG7) -> 0 | AI7: =MINUTE(AG7)/60 -> 0 | AJ7: =AH7+AI7 -> 0 | AL7: =SUM(C7:Q7)-AJ7 -> 0
A8: =A7+1 -> 46058 | B8: =IFERROR(VLOOKUP(A8, Feiertage!$B:$C, 2, 0), IF(OR(WEEKDAY(A8,2)=6, WEEKDAY(A8,2)=7), Feiertage!$C$23, "")) | R8: 0 | S8: =SUM(C8:Q8) -> 0 | T8: =S8-R8 -> 0 | U8: =U7+T8 -> 0 | X8: =V8+W8*Summen!$B$44 -> 0 | AG8: =(Z8-Y8)+(AB8-AA8)+(AD8-AC8)+(AF8-AE8) -> 0 | AH8: =HOUR(AG8) -> 0 | AI8: =MINUTE(AG8)/60 -> 0 | AJ8: =AH8+AI8 -> 0 | AL8: =SUM(C8:Q8)-AJ8 -> 0
A9: =A8+1 -> 46059 | B9: =IFERROR(VLOOKUP(A9, Feiertage!$B:$C, 2, 0), IF(OR(WEEKDAY(A9,2)=6, WEEKDAY(A9,2)=7), Feiertage!$C$23, "")) | R9: 0 | S9: =SUM(C9:Q9) -> 0 | T9: =S9-R9 -> 0 | U9: =U8+T9 -> 0 | X9: =V9+W9*Summen!$B$44 -> 0 | AG9: =(Z9-Y9)+(AB9-AA9)+(AD9-AC9)+(AF9-AE9) -> 0 | AH9: =HOUR(AG9) -> 0 | AI9: =MINUTE(AG9)/60 -> 0 | AJ9: =AH9+AI9 -> 0 | AL9: =SUM(C9:Q9)-AJ9 -> 0
A10: =A9+1 -> 46060 | B10: =IFERROR(VLOOKUP(A10, Feiertage!$B:$C, 2, 0), IF(OR(WEEKDAY(A10,2)=6, WEEKDAY(A10,2)=7), Feiertage!$C$23, "")) -> * * * * * * * * Wochenende * * * * * * * * * * * * * * * * * * * * * * * * * * * * * * * * * * * * * * * * * * * * * * * * | R10: =IF(OR(WEEKDAY(A10,2)=6,WEEKDAY(A10,2)=7),0,IFERROR(IF(VLOOKUP(A10,Feiertage!$B:$D,3,0)="ja",0,Summen!$B$9),Summen!$B$9)) -> 0 | S10: =SUM(C10:Q10) -> 0 | T10: =S10-R10 -> 0 | U10: =U9+T10 -> 0 | X10: =V10+W10*Summen!$B$44 -> 0 | AG10: =(Z10-Y10)+(AB10-AA10)+(AD10-AC10)+(AF10-AE10) -> 0 | AH10: =HOUR(AG10) -> 0 | AI10: =MINUTE(AG10)/60 -> 0 | AJ10: =AH10+AI10 -> 0 | AL10: =SUM(C10:Q10)-AJ10 -> 0
A11: =A10+1 -> 46061 | B11: =IFERROR(VLOOKUP(A11, Feiertage!$B:$C, 2, 0), IF(OR(WEEKDAY(A11,2)=6, WEEKDAY(A11,2)=7), Feiertage!$C$23, "")) -> * * * * * * * * Wochenende * * * * * * * * * * * * * * * * * * * * * * * * * * * * * * * * * * * * * * * * * * * * * * * * | R11: =IF(OR(WEEKDAY(A11,2)=6,WEEKDAY(A11,2)=7),0,IFERROR(IF(VLOOKUP(A11,Feiertage!$B:$D,3,0)="ja",0,Summen!$B$9),Summen!$B$9)) -> 0 | S11: =SUM(C11:Q11) -> 0 | T11: =S11-R11 -> 0 | U11: =U10+T11 -> 0 | X11: =V11+W11*Summen!$B$44 -> 0 | AG11: =(Z11-Y11)+(AB11-AA11)+(AD11-AC11)+(AF11-AE11) -> 0 | AH11: =HOUR(AG11) -> 0 | AI11: =MINUTE(AG11)/60 -> 0 | AJ11: =AH11+AI11 -> 0 | AL11: =SUM(C11:Q11)-AJ11 -> 0
A12: =A11+1 -> 46062 | B12: =IFERROR(VLOOKUP(A12, Feiertage!$B:$C, 2, 0), IF(OR(WEEKDAY(A12,2)=6, WEEKDAY(A12,2)=7), Feiertage!$C$23, "")) | R12: 0 | S12: =SUM(C12:Q12) -> 0 | T12: =S12-R12 -> 0 | U12: =U11+T12 -> 0 | X12: =V12+W12*Summen!$B$44 -> 0 | AG12: =(Z12-Y12)+(AB12-AA12)+(AD12-AC12)+(AF12-AE12) -> 0 | AH12: =HOUR(AG12) -> 0 | AI12: =MINUTE(AG12)/60 -> 0 | AJ12: =AH12+AI12 -> 0 | AL12: =SUM(C12:Q12)-AJ12 -> 0
A13: =A12+1 -> 46063 | B13: =IFERROR(VLOOKUP(A13, Feiertage!$B:$C, 2, 0), IF(OR(WEEKDAY(A13,2)=6, WEEKDAY(A13,2)=7), Feiertage!$C$23, "")) | R13: 0 | S13: =SUM(C13:Q13) -> 0 | T13: =S13-R13 -> 0 | U13: =U12+T13 -> 0 | X13: =V13+W13*Summen!$B$44 -> 0 | AG13: =(Z13-Y13)+(AB13-AA13)+(AD13-AC13)+(AF13-AE13) -> 0 | AH13: =HOUR(AG13) -> 0 | AI13: =MINUTE(AG13)/60 -> 0 | AJ13: =AH13+AI13 -> 0 | AL13: =SUM(C13:Q13)-AJ13 -> 0
A14: =A13+1 -> 46064 | B14: =IFERROR(VLOOKUP(A14, Feiertage!$B:$C, 2, 0), IF(OR(WEEKDAY(A14,2)=6, WEEKDAY(A14,2)=7), Feiertage!$C$23, "")) | R14: 0 | S14: =SUM(C14:Q14) -> 0 | T14: =S14-R14 -> 0 | U14: =U13+T14 -> 0 | X14: =V14+W14*Summen!$B$44 -> 0 | AG14: =(Z14-Y14)+(AB14-AA14)+(AD14-AC14)+(AF14-AE14) -> 0 | AH14: =HOUR(AG14) -> 0 | AI14: =MINUTE(AG14)/60 -> 0 | AJ14: =AH14+AI14 -> 0 | AL14: =SUM(C14:Q14)-AJ14 -> 0
A15: =A14+1 -> 46065 | B15: =IFERROR(VLOOKUP(A15, Feiertage!$B:$C, 2, 0), IF(OR(WEEKDAY(A15,2)=6, WEEKDAY(A15,2)=7), Feiertage!$C$23, "")) | R15: 0 | S15: =SUM(C15:Q15) -> 0 | T15: =S15-R15 -> 0 | U15: =U14+T15 -> 0 | X15: =V15+W15*Summen!$B$44 -> 0 | AG15: =(Z15-Y15)+(AB15-AA15)+(AD15-AC15)+(AF15-AE15) -> 0 | AH15: =HOUR(AG15) -> 0 | AI15: =MINUTE(AG15)/60 -> 0 | AJ15: =AH15+AI15 -> 0 | AL15: =SUM(C15:Q15)-AJ15 -> 0
A16: =A15+1 -> 46066 | B16: =IFERROR(VLOOKUP(A16, Feiertage!$B:$C, 2, 0), IF(OR(WEEKDAY(A16,2)=6, WEEKDAY(A16,2)=7), Feiertage!$C$23, "")) | R16: 0 | S16: =SUM(C16:Q16) -> 0 | T16: =S16-R16 -> 0 | U16: =U15+T16 -> 0 | X16: =V16+W16*Summen!$B$44 -> 0 | AG16: =(Z16-Y16)+(AB16-AA16)+(AD16-AC16)+(AF16-AE16) -> 0 | AH16: =HOUR(AG16) -> 0 | AI16: =MINUTE(AG16)/60 -> 0 | AJ16: =AH16+AI16 -> 0 | AL16: =SUM(C16:Q16)-AJ16 -> 0
A17: =A16+1 -> 46067 | B17: =IFERROR(VLOOKUP(A17, Feiertage!$B:$C, 2, 0), IF(OR(WEEKDAY(A17,2)=6, WEEKDAY(A17,2)=7), Feiertage!$C$23, "")) -> * * * * * * * * Wochenende * * * * * * * * * * * * * * * * * * * * * * * * * * * * * * * * * * * * * * * * * * * * * * * * | R17: =IF(OR(WEEKDAY(A17,2)=6,WEEKDAY(A17,2)=7),0,IFERROR(IF(VLOOKUP(A17,Feiertage!$B:$D,3,0)="ja",0,Summen!$B$9),Summen!$B$9)) -> 0 | S17: =SUM(C17:Q17) -> 0 | T17: =S17-R17 -> 0 | U17: =U16+T17 -> 0 | X17: =V17+W17*Summen!$B$44 -> 0 | AG17: =(Z17-Y17)+(AB17-AA17)+(AD17-AC17)+(AF17-AE17) -> 0 | AH17: =HOUR(AG17) -> 0 | AI17: =MINUTE(AG17)/60 -> 0 | AJ17: =AH17+AI17 -> 0 | AL17: =SUM(C17:Q17)-AJ17 -> 0
A18: =A17+1 -> 46068 | B18: =IFERROR(VLOOKUP(A18, Feiertage!$B:$C, 2, 0), IF(OR(WEEKDAY(A18,2)=6, WEEKDAY(A18,2)=7), Feiertage!$C$23, "")) -> * * * * * * * * Wochenende * * * * * * * * * * * * * * * * * * * * * * * * * * * * * * * * * * * * * * * * * * * * * * * * | R18: =IF(OR(WEEKDAY(A18,2)=6,WEEKDAY(A18,2)=7),0,IFERROR(IF(VLOOKUP(A18,Feiertage!$B:$D,3,0)="ja",0,Summen!$B$9),Summen!$B$9)) -> 0 | S18: =SUM(C18:Q18) -> 0 | T18: =S18-R18 -> 0 | U18: =U17+T18 -> 0 | X18: =V18+W18*Summen!$B$44 -> 0 | AG18: =(Z18-Y18)+(AB18-AA18)+(AD18-AC18)+(AF18-AE18) -> 0 | AH18: =HOUR(AG18) -> 0 | AI18: =MINUTE(AG18)/60 -> 0 | AJ18: =AH18+AI18 -> 0 | AL18: =SUM(C18:Q18)-AJ18 -> 0
A19: =A18+1 -> 46069 | B19: =IFERROR(VLOOKUP(A19, Feiertage!$B:$C, 2, 0), IF(OR(WEEKDAY(A19,2)=6, WEEKDAY(A19,2)=7), Feiertage!$C$23, "")) | R19: 0 | S19: =SUM(C19:Q19) -> 0 | T19: =S19-R19 -> 0 | U19: =U18+T19 -> 0 | X19: =V19+W19*Summen!$B$44 -> 0 | AG19: =(Z19-Y19)+(AB19-AA19)+(AD19-AC19)+(AF19-AE19) -> 0 | AH19: =HOUR(AG19) -> 0 | AI19: =MINUTE(AG19)/60 -> 0 | AJ19: =AH19+AI19 -> 0 | AL19: =SUM(C19:Q19)-AJ19 -> 0
A20: =A19+1 -> 46070 | B20: =IFERROR(VLOOKUP(A20, Feiertage!$B:$C, 2, 0), IF(OR(WEEKDAY(A20,2)=6, WEEKDAY(A20,2)=7), Feiertage!$C$23, "")) | R20: 0 | S20: =SUM(C20:Q20) -> 0 | T20: =S20-R20 -> 0 | U20: =U19+T20 -> 0 | X20: =V20+W20*Summen!$B$44 -> 0 | AG20: =(Z20-Y20)+(AB20-AA20)+(AD20-AC20)+(AF20-AE20) -> 0 | AH20: =HOUR(AG20) -> 0 | AI20: =MINUTE(AG20)/60 -> 0 | AJ20: =AH20+AI20 -> 0 | AL20: =SUM(C20:Q20)-AJ20 -> 0
A21: =A20+1 -> 46071 | B21: =IFERROR(VLOOKUP(A21, Feiertage!$B:$C, 2, 0), IF(OR(WEEKDAY(A21,2)=6, WEEKDAY(A21,2)=7), Feiertage!$C$23, "")) | R21: 0 | S21: =SUM(C21:Q21) -> 0 | T21: =S21-R21 -> 0 | U21: =U20+T21 -> 0 | X21: =V21+W21*Summen!$B$44 -> 0 | AG21: =(Z21-Y21)+(AB21-AA21)+(AD21-AC21)+(AF21-AE21) -> 0 | AH21: =HOUR(AG21) -> 0 | AI21: =MINUTE(AG21)/60 -> 0 | AJ21: =AH21+AI21 -> 0 | AL21: =SUM(C21:Q21)-AJ21 -> 0
A22: =A21+1 -> 46072 | B22: =IFERROR(VLOOKUP(A22, Feiertage!$B:$C, 2, 0), IF(OR(WEEKDAY(A22,2)=6, WEEKDAY(A22,2)=7), Feiertage!$C$23, "")) | R22: 0 | S22: =SUM(C22:Q22) -> 0 | T22: =S22-R22 -> 0 | U22: =U21+T22 -> 0 | X22: =V22+W22*Summen!$B$44 -> 0 | AG22: =(Z22-Y22)+(AB22-AA22)+(AD22-AC22)+(AF22-AE22) -> 0 | AH22: =HOUR(AG22) -> 0 | AI22: =MINUTE(AG22)/60 -> 0 | AJ22: =AH22+AI22 -> 0 | AL22: =SUM(C22:Q22)-AJ22 -> 0
A23: =A22+1 -> 46073 | B23: =IFERROR(VLOOKUP(A23, Feiertage!$B:$C, 2, 0), IF(OR(WEEKDAY(A23,2)=6, WEEKDAY(A23,2)=7), Feiertage!$C$23, "")) | R23: 0 | S23: =SUM(C23:Q23) -> 0 | T23: =S23-R23 -> 0 | U23: =U22+T23 -> 0 | X23: =V23+W23*Summen!$B$44 -> 0 | AG23: =(Z23-Y23)+(AB23-AA23)+(AD23-AC23)+(AF23-AE23) -> 0 | AH23: =HOUR(AG23) -> 0 | AI23: =MINUTE(AG23)/60 -> 0 | AJ23: =AH23+AI23 -> 0 | AL23: =SUM(C23:Q23)-AJ23 -> 0
A24: =A23+1 -> 46074 | B24: =IFERROR(VLOOKUP(A24, Feiertage!$B:$C, 2, 0), IF(OR(WEEKDAY(A24,2)=6, WEEKDAY(A24,2)=7), Feiertage!$C$23, "")) -> * * * * * * * * Wochenende * * * * * * * * * * * * * * * * * * * * * * * * * * * * * * * * * * * * * * * * * * * * * * * * | R24: =IF(OR(WEEKDAY(A24,2)=6,WEEKDAY(A24,2)=7),0,IFERROR(IF(VLOOKUP(A24,Feiertage!$B:$D,3,0)="ja",0,Summen!$B$9),Summen!$B$9)) -> 0 | S24: =SUM(C24:Q24) -> 0 | T24: =S24-R24 -> 0 | U24: =U23+T24 -> 0 | X24: =V24+W24*Summen!$B$44 -> 0 | AG24: =(Z24-Y24)+(AB24-AA24)+(AD24-AC24)+(AF24-AE24) -> 0 | AH24: =HOUR(AG24) -> 0 | AI24: =MINUTE(AG24)/60 -> 0 | AJ24: =AH24+AI24 -> 0 | AL24: =SUM(C24:Q24)-AJ24 -> 0
A25: =A24+1 -> 46075 | B25: =IFERROR(VLOOKUP(A25, Feiertage!$B:$C, 2, 0), IF(OR(WEEKDAY(A25,2)=6, WEEKDAY(A25,2)=7), Feiertage!$C$23, "")) -> * * * * * * * * Wochenende * * * * * * * * * * * * * * * * * * * * * * * * * * * * * * * * * * * * * * * * * * * * * * * * | R25: =IF(OR(WEEKDAY(A25,2)=6,WEEKDAY(A25,2)=7),0,IFERROR(IF(VLOOKUP(A25,Feiertage!$B:$D,3,0)="ja",0,Summen!$B$9),Summen!$B$9)) -> 0 | S25: =SUM(C25:Q25) -> 0 | T25: =S25-R25 -> 0 | U25: =U24+T25 -> 0 | X25: =V25+W25*Summen!$B$44 -> 0 | AG25: =(Z25-Y25)+(AB25-AA25)+(AD25-AC25)+(AF25-AE25) -> 0 | AH25: =HOUR(AG25) -> 0 | AI25: =MINUTE(AG25)/60 -> 0 | AJ25: =AH25+AI25 -> 0 | AL25: =SUM(C25:Q25)-AJ25 -> 0
A26: =A25+1 -> 46076 | B26: =IFERROR(VLOOKUP(A26, Feiertage!$B:$C, 2, 0), IF(OR(WEEKDAY(A26,2)=6, WEEKDAY(A26,2)=7), Feiertage!$C$23, "")) | R26: 0 | S26: =SUM(C26:Q26) -> 0 | T26: =S26-R26 -> 0 | U26: =U25+T26 -> 0 | X26: =V26+W26*Summen!$B$44 -> 0 | AG26: =(Z26-Y26)+(AB26-AA26)+(AD26-AC26)+(AF26-AE26) -> 0 | AH26: =HOUR(AG26) -> 0 | AI26: =MINUTE(AG26)/60 -> 0 | AJ26: =AH26+AI26 -> 0 | AL26: =SUM(C26:Q26)-AJ26 -> 0
A27: =A26+1 -> 46077 | B27: =IFERROR(VLOOKUP(A27, Feiertage!$B:$C, 2, 0), IF(OR(WEEKDAY(A27,2)=6, WEEKDAY(A27,2)=7), Feiertage!$C$23, "")) | R27: 0 | S27: =SUM(C27:Q27) -> 0 | T27: =S27-R27 -> 0 | U27: =U26+T27 -> 0 | X27: =V27+W27*Summen!$B$44 -> 0 | AG27: =(Z27-Y27)+(AB27-AA27)+(AD27-AC27)+(AF27-AE27) -> 0 | AH27: =HOUR(AG27) -> 0 | AI27: =MINUTE(AG27)/60 -> 0 | AJ27: =AH27+AI27 -> 0 | AL27: =SUM(C27:Q27)-AJ27 -> 0
A28: =A27+1 -> 46078 | B28: =IFERROR(VLOOKUP(A28, Feiertage!$B:$C, 2, 0), IF(OR(WEEKDAY(A28,2)=6, WEEKDAY(A28,2)=7), Feiertage!$C$23, "")) | R28: 0 | S28: =SUM(C28:Q28) -> 0 | T28: =S28-R28 -> 0 | U28: =U27+T28 -> 0 | X28: =V28+W28*Summen!$B$44 -> 0 | AG28: =(Z28-Y28)+(AB28-AA28)+(AD28-AC28)+(AF28-AE28) -> 0 | AH28: =HOUR(AG28) -> 0 | AI28: =MINUTE(AG28)/60 -> 0 | AJ28: =AH28+AI28 -> 0 | AL28: =SUM(C28:Q28)-AJ28 -> 0
A29: =A28+1 -> 46079 | B29: =IFERROR(VLOOKUP(A29, Feiertage!$B:$C, 2, 0), IF(OR(WEEKDAY(A29,2)=6, WEEKDAY(A29,2)=7), Feiertage!$C$23, "")) | R29: 0 | S29: =SUM(C29:Q29) -> 0 | T29: =S29-R29 -> 0 | U29: =U28+T29 -> 0 | X29: =V29+W29*Summen!$B$44 -> 0 | AG29: =(Z29-Y29)+(AB29-AA29)+(AD29-AC29)+(AF29-AE29) -> 0 | AH29: =HOUR(AG29) -> 0 | AI29: =MINUTE(AG29)/60 -> 0 | AJ29: =AH29+AI29 -> 0 | AL29: =SUM(C29:Q29)-AJ29 -> 0
A30: =A29+1 -> 46080 | B30: =IFERROR(VLOOKUP(A30, Feiertage!$B:$C, 2, 0), IF(OR(WEEKDAY(A30,2)=6, WEEKDAY(A30,2)=7), Feiertage!$C$23, "")) | R30: 0 | S30: =SUM(C30:Q30) -> 0 | T30: =S30-R30 -> 0 | U30: =U29+T30 -> 0 | X30: =V30+W30*Summen!$B$44 -> 0 | AG30: =(Z30-Y30)+(AB30-AA30)+(AD30-AC30)+(AF30-AE30) -> 0 | AH30: =HOUR(AG30) -> 0 | AI30: =MINUTE(AG30)/60 -> 0 | AJ30: =AH30+AI30 -> 0 | AL30: =SUM(C30:Q30)-AJ30 -> 0
A31: =A30+1 -> 46081 | B31: =IFERROR(VLOOKUP(A31, Feiertage!$B:$C, 2, 0), IF(OR(WEEKDAY(A31,2)=6, WEEKDAY(A31,2)=7), Feiertage!$C$23, "")) -> * * * * * * * * Wochenende * * * * * * * * * * * * * * * * * * * * * * * * * * * * * * * * * * * * * * * * * * * * * * * * | R31: =IF(OR(WEEKDAY(A31,2)=6,WEEKDAY(A31,2)=7),0,IFERROR(IF(VLOOKUP(A31,Feiertage!$B:$D,3,0)="ja",0,Summen!$B$9),Summen!$B$9)) -> 0 | S31: =SUM(C31:Q31) -> 0 | T31: =S31-R31 -> 0 | U31: =U30+T31 -> 0 | X31: =V31+W31*Summen!$B$44 -> 0 | AG31: =(Z31-Y31)+(AB31-AA31)+(AD31-AC31)+(AF31-AE31) -> 0 | AH31: =HOUR(AG31) -> 0 | AI31: =MINUTE(AG31)/60 -> 0 | AJ31: =AH31+AI31 -> 0 | AL31: =SUM(C31:Q31)-AJ31 -> 0
A32: Total | C32: =SUM(C4:C31) -> 0 | D32: =SUM(D4:D31) -> 0 | E32: =SUM(E4:E31) -> 0 | F32: =SUM(F4:F31) -> 0 | G32: =SUM(G4:G31) -> 0 | H32: =SUM(H4:H31) -> 0 | I32: =SUM(I4:I31) -> 0 | J32: =SUM(J4:J31) -> 0 | ... T32: =SUM(T4:T31) -> 0 | U32: =U31 -> 0 | V32: =SUM(V4:V31) -> 0 | W32: =SUM(W4:W31)*Summen!$B$44 -> 0 | X32: =V32+W32 -> 0 | AJ32: =SUM(AJ4:AJ31) -> 0 | AL32: =SUM(C32:Q32)-AJ32 -> 0
AA44: :

Sheet Mar
A1: =Summen!B1 -> Alta Engineering AG | F1: Monatsblatt | H1: Name: | J1: =Summen!B3 -> Michael Küng | N1: Monat: | P1: =Feb!P1+28 -> 46082 | S1: Anstellung : | U1: =Summen!B5 -> 1 | W1: Blatt Nr. | X1: =Feb!X1+1 -> 3
C2: Ferien: | E2: =Summen!B18 -> 10.8 | F2: Bezogen: | H2: =Feb!H2+(Feb!Q32/Summen!B9) -> 0 | I2: Rest: | J2: =E2-H2 -> 10.8 | T2: Stundenübertrag Vormonat : | U2: =Feb!U32 -> 0 | V2: Spesen
A3: Projekte | L3: krank | M3: Reisezeit | N3: CAD | O3: Ausbildung | P3: Büro | Q3: Ferien | R3: Soll | S3: Ist | T3: +/- | U3: Stand | V3: Fr. | W3: Km | X3: Summe | Y3: Start [hh:mm] | Z3: Stop [hh:mm] | AA3: Start [hh:mm] | AB3: Stop [hh:mm] | AC3: Start [hh:mm] | AD3: Stop [hh:mm] | AE3: Start [hh:mm] | AF3: Stop [hh:mm] | AG3: Ist-Zeit [hh:mm] | AH3: Ist-Zeit [hh] | AI3: Ist-Zeit [.hh] | AJ3: Ist-Zeit [h.h] | AL3: Aufteilung - Istzeit
A4: =P1 -> 46082 | B4: =IFERROR(VLOOKUP(A4, Feiertage!$B:$C, 2, 0), IF(OR(WEEKDAY(A4,2)=6, WEEKDAY(A4,2)=7), Feiertage!$C$23, "")) -> * * * * * * * * Wochenende * * * * * * * * * * * * * * * * * * * * * * * * * * * * * * * * * * * * * * * * * * * * * * * * | R4: =IF(OR(WEEKDAY(A4,2)=6,WEEKDAY(A4,2)=7),0,IFERROR(IF(VLOOKUP(A4,Feiertage!$B:$D,3,0)="ja",0,Summen!$B$9),Summen!$B$9)) -> 0 | S4: =SUM(C4:Q4) -> 0 | T4: =S4-R4 -> 0 | U4: =U2+T4 -> 0 | X4: =V4+W4*Summen!$B$44 -> 0 | AG4: =(Z4-Y4)+(AB4-AA4)+(AD4-AC4)+(AF4-AE4) -> 0 | AH4: =HOUR(AG4) -> 0 | AI4: =MINUTE(AG4)/60 -> 0 | AJ4: =AH4+AI4 -> 0 | AL4: =SUM(C4:Q4)-AJ4 -> 0
A5: =A4+1 -> 46083 | B5: =IFERROR(VLOOKUP(A5, Feiertage!$B:$C, 2, 0), IF(OR(WEEKDAY(A5,2)=6, WEEKDAY(A5,2)=7), Feiertage!$C$23, "")) | R5: 0 | S5: =SUM(C5:Q5) -> 0 | T5: =S5-R5 -> 0 | U5: =U4+T5 -> 0 | X5: =V5+W5*Summen!$B$44 -> 0 | AG5: =(Z5-Y5)+(AB5-AA5)+(AD5-AC5)+(AF5-AE5) -> 0 | AH5: =HOUR(AG5) -> 0 | AI5: =MINUTE(AG5)/60 -> 0 | AJ5: =AH5+AI5 -> 0 | AL5: =SUM(C5:Q5)-AJ5 -> 0
A6: =A5+1 -> 46084 | B6: =IFERROR(VLOOKUP(A6, Feiertage!$B:$C, 2, 0), IF(OR(WEEKDAY(A6,2)=6, WEEKDAY(A6,2)=7), Feiertage!$C$23, "")) | R6: 0 | S6: =SUM(C6:Q6) -> 0 | T6: =S6-R6 -> 0 | U6: =U5+T6 -> 0 | X6: =V6+W6*Summen!$B$44 -> 0 | AG6: =(Z6-Y6)+(AB6-AA6)+(AD6-AC6)+(AF6-AE6) -> 0 | AH6: =HOUR(AG6) -> 0 | AI6: =MINUTE(AG6)/60 -> 0 | AJ6: =AH6+AI6 -> 0 | AL6: =SUM(C6:Q6)-AJ6 -> 0
A7: =A6+1 -> 46085 | B7: =IFERROR(VLOOKUP(A7, Feiertage!$B:$C, 2, 0), IF(OR(WEEKDAY(A7,2)=6, WEEKDAY(A7,2)=7), Feiertage!$C$23, "")) | R7: 0 | S7: =SUM(C7:Q7) -> 0 | T7: =S7-R7 -> 0 | U7: =U6+T7 -> 0 | X7: =V7+W7*Summen!$B$44 -> 0 | AG7: =(Z7-Y7)+(AB7-AA7)+(AD7-AC7)+(AF7-AE7) -> 0 | AH7: =HOUR(AG7) -> 0 | AI7: =MINUTE(AG7)/60 -> 0 | AJ7: =AH7+AI7 -> 0 | AL7: =SUM(C7:Q7)-AJ7 -> 0
A8: =A7+1 -> 46086 | B8: =IFERROR(VLOOKUP(A8, Feiertage!$B:$C, 2, 0), IF(OR(WEEKDAY(A8,2)=6, WEEKDAY(A8,2)=7), Feiertage!$C$23, "")) | R8: 0 | S8: =SUM(C8:Q8) -> 0 | T8: =S8-R8 -> 0 | U8: =U7+T8 -> 0 | X8: =V8+W8*Summen!$B$44 -> 0 | AG8: =(Z8-Y8)+(AB8-AA8)+(AD8-AC8)+(AF8-AE8) -> 0 | AH8: =HOUR(AG8) -> 0 | AI8: =MINUTE(AG8)/60 -> 0 | AJ8: =AH8+AI8 -> 0 | AL8: =SUM(C8:Q8)-AJ8 -> 0
A9: =A8+1 -> 46087 | B9: =IFERROR(VLOOKUP(A9, Feiertage!$B:$C, 2, 0), IF(OR(WEEKDAY(A9,2)=6, WEEKDAY(A9,2)=7), Feiertage!$C$23, "")) | R9: 0 | S9: =SUM(C9:Q9) -> 0 | T9: =S9-R9 -> 0 | U9: =U8+T9 -> 0 | X9: =V9+W9*Summen!$B$44 -> 0 | AG9: =(Z9-Y9)+(AB9-AA9)+(AD9-AC9)+(AF9-AE9) -> 0 | AH9: =HOUR(AG9) -> 0 | AI9: =MINUTE(AG9)/60 -> 0 | AJ9: =AH9+AI9 -> 0 | AL9: =SUM(C9:Q9)-AJ9 -> 0
A10: =A9+1 -> 46088 | B10: =IFERROR(VLOOKUP(A10, Feiertage!$B:$C, 2, 0), IF(OR(WEEKDAY(A10,2)=6, WEEKDAY(A10,2)=7), Feiertage!$C$23, "")) -> * * * * * * * * Wochenende * * * * * * * * * * * * * * * * * * * * * * * * * * * * * * * * * * * * * * * * * * * * * * * * | R10: =IF(OR(WEEKDAY(A10,2)=6,WEEKDAY(A10,2)=7),0,IFERROR(IF(VLOOKUP(A10,Feiertage!$B:$D,3,0)="ja",0,Summen!$B$9),Summen!$B$9)) -> 0 | S10: =SUM(C10:Q10) -> 0 | T10: =S10-R10 -> 0 | U10: =U9+T10 -> 0 | X10: =V10+W10*Summen!$B$44 -> 0 | AG10: =(Z10-Y10)+(AB10-AA10)+(AD10-AC10)+(AF10-AE10) -> 0 | AH10: =HOUR(AG10) -> 0 | AI10: =MINUTE(AG10)/60 -> 0 | AJ10: =AH10+AI10 -> 0 | AL10: =SUM(C10:Q10)-AJ10 -> 0
A11: =A10+1 -> 46089 | B11: =IFERROR(VLOOKUP(A11, Feiertage!$B:$C, 2, 0), IF(OR(WEEKDAY(A11,2)=6, WEEKDAY(A11,2)=7), Feiertage!$C$23, "")) -> * * * * * * * * Wochenende * * * * * * * * * * * * * * * * * * * * * * * * * * * * * * * * * * * * * * * * * * * * * * * * | R11: =IF(OR(WEEKDAY(A11,2)=6,WEEKDAY(A11,2)=7),0,IFERROR(IF(VLOOKUP(A11,Feiertage!$B:$D,3,0)="ja",0,Summen!$B$9),Summen!$B$9)) -> 0 | S11: =SUM(C11:Q11) -> 0 | T11: =S11-R11 -> 0 | U11: =U10+T11 -> 0 | X11: =V11+W11*Summen!$B$44 -> 0 | AG11: =(Z11-Y11)+(AB11-AA11)+(AD11-AC11)+(AF11-AE11) -> 0 | AH11: =HOUR(AG11) -> 0 | AI11: =MINUTE(AG11)/60 -> 0 | AJ11: =AH11+AI11 -> 0 | AL11: =SUM(C11:Q11)-AJ11 -> 0
A12: =A11+1 -> 46090 | B12: =IFERROR(VLOOKUP(A12, Feiertage!$B:$C, 2, 0), IF(OR(WEEKDAY(A12,2)=6, WEEKDAY(A12,2)=7), Feiertage!$C$23, "")) | R12: 0 | S12: =SUM(C12:Q12) -> 0 | T12: =S12-R12 -> 0 | U12: =U11+T12 -> 0 | X12: =V12+W12*Summen!$B$44 -> 0 | AG12: =(Z12-Y12)+(AB12-AA12)+(AD12-AC12)+(AF12-AE12) -> 0 | AH12: =HOUR(AG12) -> 0 | AI12: =MINUTE(AG12)/60 -> 0 | AJ12: =AH12+AI12 -> 0 | AL12: =SUM(C12:Q12)-AJ12 -> 0
A13: =A12+1 -> 46091 | B13: =IFERROR(VLOOKUP(A13, Feiertage!$B:$C, 2, 0), IF(OR(WEEKDAY(A13,2)=6, WEEKDAY(A13,2)=7), Feiertage!$C$23, "")) | R13: 0 | S13: =SUM(C13:Q13) -> 0 | T13: =S13-R13 -> 0 | U13: =U12+T13 -> 0 | X13: =V13+W13*Summen!$B$44 -> 0 | AG13: =(Z13-Y13)+(AB13-AA13)+(AD13-AC13)+(AF13-AE13) -> 0 | AH13: =HOUR(AG13) -> 0 | AI13: =MINUTE(AG13)/60 -> 0 | AJ13: =AH13+AI13 -> 0 | AL13: =SUM(C13:Q13)-AJ13 -> 0
A14: =A13+1 -> 46092 | B14: =IFERROR(VLOOKUP(A14, Feiertage!$B:$C, 2, 0), IF(OR(WEEKDAY(A14,2)=6, WEEKDAY(A14,2)=7), Feiertage!$C$23, "")) | R14: 0 | S14: =SUM(C14:Q14) -> 0 | T14: =S14-R14 -> 0 | U14: =U13+T14 -> 0 | X14: =V14+W14*Summen!$B$44 -> 0 | AG14: =(Z14-Y14)+(AB14-AA14)+(AD14-AC14)+(AF14-AE14) -> 0 | AH14: =HOUR(AG14) -> 0 | AI14: =MINUTE(AG14)/60 -> 0 | AJ14: =AH14+AI14 -> 0 | AL14: =SUM(C14:Q14)-AJ14 -> 0
A15: =A14+1 -> 46093 | B15: =IFERROR(VLOOKUP(A15, Feiertage!$B:$C, 2, 0), IF(OR(WEEKDAY(A15,2)=6, WEEKDAY(A15,2)=7), Feiertage!$C$23, "")) | R15: 0 | S15: =SUM(C15:Q15) -> 0 | T15: =S15-R15 -> 0 | U15: =U14+T15 -> 0 | X15: =V15+W15*Summen!$B$44 -> 0 | AG15: =(Z15-Y15)+(AB15-AA15)+(AD15-AC15)+(AF15-AE15) -> 0 | AH15: =HOUR(AG15) -> 0 | AI15: =MINUTE(AG15)/60 -> 0 | AJ15: =AH15+AI15 -> 0 | AL15: =SUM(C15:Q15)-AJ15 -> 0
A16: =A15+1 -> 46094 | B16: =IFERROR(VLOOKUP(A16, Feiertage!$B:$C, 2, 0), IF(OR(WEEKDAY(A16,2)=6, WEEKDAY(A16,2)=7), Feiertage!$C$23, "")) | R16: 0 | S16: =SUM(C16:Q16) -> 0 | T16: =S16-R16 -> 0 | U16: =U15+T16 -> 0 | X16: =V16+W16*Summen!$B$44 -> 0 | AG16: =(Z16-Y16)+(AB16-AA16)+(AD16-AC16)+(AF16-AE16) -> 0 | AH16: =HOUR(AG16) -> 0 | AI16: =MINUTE(AG16)/60 -> 0 | AJ16: =AH16+AI16 -> 0 | AL16: =SUM(C16:Q16)-AJ16 -> 0
A17: =A16+1 -> 46095 | B17: =IFERROR(VLOOKUP(A17, Feiertage!$B:$C, 2, 0), IF(OR(WEEKDAY(A17,2)=6, WEEKDAY(A17,2)=7), Feiertage!$C$23, "")) -> * * * * * * * * Wochenende * * * * * * * * * * * * * * * * * * * * * * * * * * * * * * * * * * * * * * * * * * * * * * * * | R17: =IF(OR(WEEKDAY(A17,2)=6,WEEKDAY(A17,2)=7),0,IFERROR(IF(VLOOKUP(A17,Feiertage!$B:$D,3,0)="ja",0,Summen!$B$9),Summen!$B$9)) -> 0 | S17: =SUM(C17:Q17) -> 0 | T17: =S17-R17 -> 0 | U17: =U16+T17 -> 0 | X17: =V17+W17*Summen!$B$44 -> 0 | AG17: =(Z17-Y17)+(AB17-AA17)+(AD17-AC17)+(AF17-AE17) -> 0 | AH17: =HOUR(AG17) -> 0 | AI17: =MINUTE(AG17)/60 -> 0 | AJ17: =AH17+AI17 -> 0 | AL17: =SUM(C17:Q17)-AJ17 -> 0
A18: =A17+1 -> 46096 | B18: =IFERROR(VLOOKUP(A18, Feiertage!$B:$C, 2, 0), IF(OR(WEEKDAY(A18,2)=6, WEEKDAY(A18,2)=7), Feiertage!$C$23, "")) -> * * * * * * * * Wochenende * * * * * * * * * * * * * * * * * * * * * * * * * * * * * * * * * * * * * * * * * * * * * * * * | R18: =IF(OR(WEEKDAY(A18,2)=6,WEEKDAY(A18,2)=7),0,IFERROR(IF(VLOOKUP(A18,Feiertage!$B:$D,3,0)="ja",0,Summen!$B$9),Summen!$B$9)) -> 0 | S18: =SUM(C18:Q18) -> 0 | T18: =S18-R18 -> 0 | U18: =U17+T18 -> 0 | X18: =V18+W18*Summen!$B$44 -> 0 | AG18: =(Z18-Y18)+(AB18-AA18)+(AD18-AC18)+(AF18-AE18) -> 0 | AH18: =HOUR(AG18) -> 0 | AI18: =MINUTE(AG18)/60 -> 0 | AJ18: =AH18+AI18 -> 0 | AL18: =SUM(C18:Q18)-AJ18 -> 0
A19: =A18+1 -> 46097 | B19: =IFERROR(VLOOKUP(A19, Feiertage!$B:$C, 2, 0), IF(OR(WEEKDAY(A19,2)=6, WEEKDAY(A19,2)=7), Feiertage!$C$23, "")) | R19: 0 | S19: =SUM(C19:Q19) -> 0 | T19: =S19-R19 -> 0 | U19: =U18+T19 -> 0 | X19: =V19+W19*Summen!$B$44 -> 0 | AG19: =(Z19-Y19)+(AB19-AA19)+(AD19-AC19)+(AF19-AE19) -> 0 | AH19: =HOUR(AG19) -> 0 | AI19: =MINUTE(AG19)/60 -> 0 | AJ19: =AH19+AI19 -> 0 | AL19: =SUM(C19:Q19)-AJ19 -> 0
A20: =A19+1 -> 46098 | B20: =IFERROR(VLOOKUP(A20, Feiertage!$B:$C, 2, 0), IF(OR(WEEKDAY(A20,2)=6, WEEKDAY(A20,2)=7), Feiertage!$C$23, "")) | R20: 0 | S20: =SUM(C20:Q20) -> 0 | T20: =S20-R20 -> 0 | U20: =U19+T20 -> 0 | X20: =V20+W20*Summen!$B$44 -> 0 | AG20: =(Z20-Y20)+(AB20-AA20)+(AD20-AC20)+(AF20-AE20) -> 0 | AH20: =HOUR(AG20) -> 0 | AI20: =MINUTE(AG20)/60 -> 0 | AJ20: =AH20+AI20 -> 0 | AL20: =SUM(C20:Q20)-AJ20 -> 0
A21: =A20+1 -> 46099 | B21: =IFERROR(VLOOKUP(A21, Feiertage!$B:$C, 2, 0), IF(OR(WEEKDAY(A21,2)=6, WEEKDAY(A21,2)=7), Feiertage!$C$23, "")) | R21: 0 | S21: =SUM(C21:Q21) -> 0 | T21: =S21-R21 -> 0 | U21: =U20+T21 -> 0 | X21: =V21+W21*Summen!$B$44 -> 0 | AG21: =(Z21-Y21)+(AB21-AA21)+(AD21-AC21)+(AF21-AE21) -> 0 | AH21: =HOUR(AG21) -> 0 | AI21: =MINUTE(AG21)/60 -> 0 | AJ21: =AH21+AI21 -> 0 | AL21: =SUM(C21:Q21)-AJ21 -> 0
A22: =A21+1 -> 46100 | B22: =IFERROR(VLOOKUP(A22, Feiertage!$B:$C, 2, 0), IF(OR(WEEKDAY(A22,2)=6, WEEKDAY(A22,2)=7), Feiertage!$C$23, "")) -> * * * * * * * * Josefstag * * * * * * * * * * * * * * * * * * * * * * * * * * * * * * * * * * * * * * * * * * * * * * * * * * | R22: =IF(OR(WEEKDAY(A22,2)=6,WEEKDAY(A22,2)=7),0,IFERROR(IF(VLOOKUP(A22,Feiertage!$B:$D,3,0)="ja",0,Summen!$B$9),Summen!$B$9)) -> 0 | S22: =SUM(C22:Q22) -> 0 | T22: =S22-R22 -> 0 | U22: =U21+T22 -> 0 | X22: =V22+W22*Summen!$B$44 -> 0 | AG22: =(Z22-Y22)+(AB22-AA22)+(AD22-AC22)+(AF22-AE22) -> 0 | AH22: =HOUR(AG22) -> 0 | AI22: =MINUTE(AG22)/60 -> 0 | AJ22: =AH22+AI22 -> 0 | AL22: =SUM(C22:Q22)-AJ22 -> 0
A23: =A22+1 -> 46101 | B23: =IFERROR(VLOOKUP(A23, Feiertage!$B:$C, 2, 0), IF(OR(WEEKDAY(A23,2)=6, WEEKDAY(A23,2)=7), Feiertage!$C$23, "")) | R23: 0 | S23: =SUM(C23:Q23) -> 0 | T23: =S23-R23 -> 0 | U23: =U22+T23 -> 0 | X23: =V23+W23*Summen!$B$44 -> 0 | AG23: =(Z23-Y23)+(AB23-AA23)+(AD23-AC23)+(AF23-AE23) -> 0 | AH23: =HOUR(AG23) -> 0 | AI23: =MINUTE(AG23)/60 -> 0 | AJ23: =AH23+AI23 -> 0 | AL23: =SUM(C23:Q23)-AJ23 -> 0
A24: =A23+1 -> 46102 | B24: =IFERROR(VLOOKUP(A24, Feiertage!$B:$C, 2, 0), IF(OR(WEEKDAY(A24,2)=6, WEEKDAY(A24,2)=7), Feiertage!$C$23, "")) -> * * * * * * * * Wochenende * * * * * * * * * * * * * * * * * * * * * * * * * * * * * * * * * * * * * * * * * * * * * * * * | R24: =IF(OR(WEEKDAY(A24,2)=6,WEEKDAY(A24,2)=7),0,IFERROR(IF(VLOOKUP(A24,Feiertage!$B:$D,3,0)="ja",0,Summen!$B$9),Summen!$B$9)) -> 0 | S24: =SUM(C24:Q24) -> 0 | T24: =S24-R24 -> 0 | U24: =U23+T24 -> 0 | X24: =V24+W24*Summen!$B$44 -> 0 | AG24: =(Z24-Y24)+(AB24-AA24)+(AD24-AC24)+(AF24-AE24) -> 0 | AH24: =HOUR(AG24) -> 0 | AI24: =MINUTE(AG24)/60 -> 0 | AJ24: =AH24+AI24 -> 0 | AL24: =SUM(C24:Q24)-AJ24 -> 0
A25: =A24+1 -> 46103 | B25: =IFERROR(VLOOKUP(A25, Feiertage!$B:$C, 2, 0), IF(OR(WEEKDAY(A25,2)=6, WEEKDAY(A25,2)=7), Feiertage!$C$23, "")) -> * * * * * * * * Wochenende * * * * * * * * * * * * * * * * * * * * * * * * * * * * * * * * * * * * * * * * * * * * * * * * | R25: =IF(OR(WEEKDAY(A25,2)=6,WEEKDAY(A25,2)=7),0,IFERROR(IF(VLOOKUP(A25,Feiertage!$B:$D,3,0)="ja",0,Summen!$B$9),Summen!$B$9)) -> 0 | S25: =SUM(C25:Q25) -> 0 | T25: =S25-R25 -> 0 | U25: =U24+T25 -> 0 | X25: =V25+W25*Summen!$B$44 -> 0 | AG25: =(Z25-Y25)+(AB25-AA25)+(AD25-AC25)+(AF25-AE25) -> 0 | AH25: =HOUR(AG25) -> 0 | AI25: =MINUTE(AG25)/60 -> 0 | AJ25: =AH25+AI25 -> 0 | AL25: =SUM(C25:Q25)-AJ25 -> 0
A26: =A25+1 -> 46104 | B26: =IFERROR(VLOOKUP(A26, Feiertage!$B:$C, 2, 0), IF(OR(WEEKDAY(A26,2)=6, WEEKDAY(A26,2)=7), Feiertage!$C$23, "")) | R26: 0 | S26: =SUM(C26:Q26) -> 0 | T26: =S26-R26 -> 0 | U26: =U25+T26 -> 0 | X26: =V26+W26*Summen!$B$44 -> 0 | AG26: =(Z26-Y26)+(AB26-AA26)+(AD26-AC26)+(AF26-AE26) -> 0 | AH26: =HOUR(AG26) -> 0 | AI26: =MINUTE(AG26)/60 -> 0 | AJ26: =AH26+AI26 -> 0 | AL26: =SUM(C26:Q26)-AJ26 -> 0
A27: =A26+1 -> 46105 | B27: =IFERROR(VLOOKUP(A27, Feiertage!$B:$C, 2, 0), IF(OR(WEEKDAY(A27,2)=6, WEEKDAY(A27,2)=7), Feiertage!$C$23, "")) | R27: 0 | S27: =SUM(C27:Q27) -> 0 | T27: =S27-R27 -> 0 | U27: =U26+T27 -> 0 | X27: =V27+W27*Summen!$B$44 -> 0 | AG27: =(Z27-Y27)+(AB27-AA27)+(AD27-AC27)+(AF27-AE27) -> 0 | AH27: =HOUR(AG27) -> 0 | AI27: =MINUTE(AG27)/60 -> 0 | AJ27: =AH27+AI27 -> 0 | AL27: =SUM(C27:Q27)-AJ27 -> 0
A28: =A27+1 -> 46106 | B28: =IFERROR(VLOOKUP(A28, Feiertage!$B:$C, 2, 0), IF(OR(WEEKDAY(A28,2)=6, WEEKDAY(A28,2)=7), Feiertage!$C$23, "")) | R28: 0 | S28: =SUM(C28:Q28) -> 0 | T28: =S28-R28 -> 0 | U28: =U27+T28 -> 0 | X28: =V28+W28*Summen!$B$44 -> 0 | AG28: =(Z28-Y28)+(AB28-AA28)+(AD28-AC28)+(AF28-AE28) -> 0 | AH28: =HOUR(AG28) -> 0 | AI28: =MINUTE(AG28)/60 -> 0 | AJ28: =AH28+AI28 -> 0 | AL28: =SUM(C28:Q28)-AJ28 -> 0
A29: =A28+1 -> 46107 | B29: =IFERROR(VLOOKUP(A29, Feiertage!$B:$C, 2, 0), IF(OR(WEEKDAY(A29,2)=6, WEEKDAY(A29,2)=7), Feiertage!$C$23, "")) | R29: 0 | S29: =SUM(C29:Q29) -> 0 | T29: =S29-R29 -> 0 | U29: =U28+T29 -> 0 | X29: =V29+W29*Summen!$B$44 -> 0 | AG29: =(Z29-Y29)+(AB29-AA29)+(AD29-AC29)+(AF29-AE29) -> 0 | AH29: =HOUR(AG29) -> 0 | AI29: =MINUTE(AG29)/60 -> 0 | AJ29: =AH29+AI29 -> 0 | AL29: =SUM(C29:Q29)-AJ29 -> 0
A30: =A29+1 -> 46108 | B30: =IFERROR(VLOOKUP(A30, Feiertage!$B:$C, 2, 0), IF(OR(WEEKDAY(A30,2)=6, WEEKDAY(A30,2)=7), Feiertage!$C$23, "")) | R30: 0 | S30: =SUM(C30:Q30) -> 0 | T30: =S30-R30 -> 0 | U30: =U29+T30 -> 0 | X30: =V30+W30*Summen!$B$44 -> 0 | AG30: =(Z30-Y30)+(AB30-AA30)+(AD30-AC30)+(AF30-AE30) -> 0 | AH30: =HOUR(AG30) -> 0 | AI30: =MINUTE(AG30)/60 -> 0 | AJ30: =AH30+AI30 -> 0 | AL30: =SUM(C30:Q30)-AJ30 -> 0
A31: =A30+1 -> 46109 | B31: =IFERROR(VLOOKUP(A31, Feiertage!$B:$C, 2, 0), IF(OR(WEEKDAY(A31,2)=6, WEEKDAY(A31,2)=7), Feiertage!$C$23, "")) -> * * * * * * * * Wochenende * * * * * * * * * * * * * * * * * * * * * * * * * * * * * * * * * * * * * * * * * * * * * * * * | R31: =IF(OR(WEEKDAY(A31,2)=6,WEEKDAY(A31,2)=7),0,IFERROR(IF(VLOOKUP(A31,Feiertage!$B:$D,3,0)="ja",0,Summen!$B$9),Summen!$B$9)) -> 0 | S31: =SUM(C31:Q31) -> 0 | T31: =S31-R31 -> 0 | U31: =U30+T31 -> 0 | X31: =V31+W31*Summen!$B$44 -> 0 | AG31: =(Z31-Y31)+(AB31-AA31)+(AD31-AC31)+(AF31-AE31) -> 0 | AH31: =HOUR(AG31) -> 0 | AI31: =MINUTE(AG31)/60 -> 0 | AJ31: =AH31+AI31 -> 0 | AL31: =SUM(C31:Q31)-AJ31 -> 0
A32: =A31+1 -> 46110 | B32: =IFERROR(VLOOKUP(A32, Feiertage!$B:$C, 2, 0), IF(OR(WEEKDAY(A32,2)=6, WEEKDAY(A32,2)=7), Feiertage!$C$23, "")) -> * * * * * * * * Wochenende * * * * * * * * * * * * * * * * * * * * * * * * * * * * * * * * * * * * * * * * * * * * * * * * | R32: =IF(OR(WEEKDAY(A32,2)=6,WEEKDAY(A32,2)=7),0,IFERROR(IF(VLOOKUP(A32,Feiertage!$B:$D,3,0)="ja",0,Summen!$B$9),Summen!$B$9)) -> 0 | S32: =SUM(C32:Q32) -> 0 | T32: =S32-R32 -> 0 | U32: =U31+T32 -> 0 | X32: =V32+W32*Summen!$B$44 -> 0 | AG32: =(Z32-Y32)+(AB32-AA32)+(AD32-AC32)+(AF32-AE32) -> 0 | AH32: =HOUR(AG32) -> 0 | AI32: =MINUTE(AG32)/60 -> 0 | AJ32: =AH32+AI32 -> 0 | AL32: =SUM(C32:Q32)-AJ32 -> 0
A33: =A32+1 -> 46111 | B33: =IFERROR(VLOOKUP(A33, Feiertage!$B:$C, 2, 0), IF(OR(WEEKDAY(A33,2)=6, WEEKDAY(A33,2)=7), Feiertage!$C$23, "")) | R33: 0 | S33: =SUM(C33:Q33) -> 0 | T33: =S33-R33 -> 0 | U33: =U32+T33 -> 0 | X33: =V33+W33*Summen!$B$44 -> 0 | AG33: =(Z33-Y33)+(AB33-AA33)+(AD33-AC33)+(AF33-AE33) -> 0 | AH33: =HOUR(AG33) -> 0 | AI33: =MINUTE(AG33)/60 -> 0 | AJ33: =AH33+AI33 -> 0 | AL33: =SUM(C33:Q33)-AJ33 -> 0
A34: =A33+1 -> 46112 | B34: =IFERROR(VLOOKUP(A34, Feiertage!$B:$C, 2, 0), IF(OR(WEEKDAY(A34,2)=6, WEEKDAY(A34,2)=7), Feiertage!$C$23, "")) | R34: 0 | S34: =SUM(C34:Q34) -> 0 | T34: =S34-R34 -> 0 | U34: =U33+T34 -> 0 | X34: =V34+W34*Summen!$B$44 -> 0 | AG34: =(Z34-Y34)+(AB34-AA34)+(AD34-AC34)+(AF34-AE34) -> 0 | AH34: =HOUR(AG34) -> 0 | AI34: =MINUTE(AG34)/60 -> 0 | AJ34: =AH34+AI34 -> 0 | AL34: =SUM(C34:Q34)-AJ34 -> 0
A35: Total | C35: =SUM(C4:C34) -> 0 | D35: =SUM(D4:D34) -> 0 | E35: =SUM(E4:E34) -> 0 | F35: =SUM(F4:F34) -> 0 | G35: =SUM(G4:G34) -> 0 | H35: =SUM(H4:H34) -> 0 | I35: =SUM(I4:I34) -> 0 | J35: =SUM(J4:J34) -> 0 | ... T35: =SUM(T4:T34) -> 0 | U35: =U34 -> 0 | V35: =SUM(V4:V34) -> 0 | W35: =SUM(W4:W34)*Summen!$B$44 -> 0 | X35: =V35+W35 -> 0 | AJ35: =SUM(AJ4:AJ34) -> 0 | AL35: =SUM(C35:Q35)-AJ35 -> 0

Sheet Apr
A1: =Summen!B1 -> Alta Engineering AG | F1: Monatsblatt | H1: Name: | J1: =Summen!B3 -> Michael Küng | N1: Monat: | P1: =Mar!P1+31 -> 46113 | S1: Anstellung : | U1: =Summen!B5 -> 1 | W1: Blatt Nr. | X1: =Mar!X1+1 -> 4
C2: Ferien: | E2: =Summen!B18 -> 10.8 | F2: Bezogen: | H2: =Mar!H2+(Mar!Q35/Summen!B9) -> 0 | I2: Rest: | J2: =E2-H2 -> 10.8 | T2: Stundenübertrag Vormonat : | U2: =Mar!U35 -> 0 | V2: Spesen
A3: Projekte | L3: krank | M3: Reisezeit | N3: CAD | O3: Ausbildung | P3: Büro | Q3: Ferien | R3: Soll | S3: Ist | T3: +/- | U3: Stand | V3: Fr. | W3: Km | X3: Summe | Y3: Start [hh:mm] | Z3: Stop [hh:mm] | AA3: Start [hh:mm] | AB3: Stop [hh:mm] | AC3: Start [hh:mm] | AD3: Stop [hh:mm] | AE3: Start [hh:mm] | AF3: Stop [hh:mm] | AG3: Ist-Zeit [hh:mm] | AH3: Ist-Zeit [hh] | AI3: Ist-Zeit [.hh] | AJ3: Ist-Zeit [h.h] | AL3: Aufteilung - Istzeit
A4: =P1 -> 46113 | B4: =IFERROR(VLOOKUP(A4, Feiertage!$B:$C, 2, 0), IF(OR(WEEKDAY(A4,2)=6, WEEKDAY(A4,2)=7), Feiertage!$C$23, "")) | R4: 0 | S4: =SUM(C4:Q4) -> 0 | T4: =S4-R4 -> 0 | U4: =U2+T4 -> 0 | X4: =V4+W4*Summen!$B$44 -> 0 | AG4: =(Z4-Y4)+(AB4-AA4)+(AD4-AC4)+(AF4-AE4) -> 0 | AH4: =HOUR(AG4) -> 0 | AI4: =MINUTE(AG4)/60 -> 0 | AJ4: =AH4+AI4 -> 0 | AL4: =SUM(C4:Q4)-AJ4 -> 0
A5: =A4+1 -> 46114 | B5: =IFERROR(VLOOKUP(A5, Feiertage!$B:$C, 2, 0), IF(OR(WEEKDAY(A5,2)=6, WEEKDAY(A5,2)=7), Feiertage!$C$23, "")) | R5: 0 | S5: =SUM(C5:Q5) -> 0 | T5: =S5-R5 -> 0 | U5: =U4+T5 -> 0 | X5: =V5+W5*Summen!$B$44 -> 0 | AG5: =(Z5-Y5)+(AB5-AA5)+(AD5-AC5)+(AF5-AE5) -> 0 | AH5: =HOUR(AG5) -> 0 | AI5: =MINUTE(AG5)/60 -> 0 | AJ5: =AH5+AI5 -> 0 | AL5: =SUM(C5:Q5)-AJ5 -> 0
A6: =A5+1 -> 46115 | B6: =IFERROR(VLOOKUP(A6, Feiertage!$B:$C, 2, 0), IF(OR(WEEKDAY(A6,2)=6, WEEKDAY(A6,2)=7), Feiertage!$C$23, "")) -> * * * * * * * * Karfreitag * * * * * * * * * * * * * * * * * * * * * * * * * * * * * * * * * * * * * * * * * * * * * * * * * * | R6: =IF(OR(WEEKDAY(A6,2)=6,WEEKDAY(A6,2)=7),0,IFERROR(IF(VLOOKUP(A6,Feiertage!$B:$D,3,0)="ja",0,Summen!$B$9),Summen!$B$9)) -> 0 | S6: =SUM(C6:Q6) -> 0 | T6: =S6-R6 -> 0 | U6: =U5+T6 -> 0 | X6: =V6+W6*Summen!$B$44 -> 0 | AG6: =(Z6-Y6)+(AB6-AA6)+(AD6-AC6)+(AF6-AE6) -> 0 | AH6: =HOUR(AG6) -> 0 | AI6: =MINUTE(AG6)/60 -> 0 | AJ6: =AH6+AI6 -> 0 | AL6: =SUM(C6:Q6)-AJ6 -> 0
A7: =A6+1 -> 46116 | B7: =IFERROR(VLOOKUP(A7, Feiertage!$B:$C, 2, 0), IF(OR(WEEKDAY(A7,2)=6, WEEKDAY(A7,2)=7), Feiertage!$C$23, "")) -> * * * * * * * * Wochenende * * * * * * * * * * * * * * * * * * * * * * * * * * * * * * * * * * * * * * * * * * * * * * * * | R7: =IF(OR(WEEKDAY(A7,2)=6,WEEKDAY(A7,2)=7),0,IFERROR(IF(VLOOKUP(A7,Feiertage!$B:$D,3,0)="ja",0,Summen!$B$9),Summen!$B$9)) -> 0 | S7: =SUM(C7:Q7) -> 0 | T7: =S7-R7 -> 0 | U7: =U6+T7 -> 0 | X7: =V7+W7*Summen!$B$44 -> 0 | AG7: =(Z7-Y7)+(AB7-AA7)+(AD7-AC7)+(AF7-AE7) -> 0 | AH7: =HOUR(AG7) -> 0 | AI7: =MINUTE(AG7)/60 -> 0 | AJ7: =AH7+AI7 -> 0 | AL7: =SUM(C7:Q7)-AJ7 -> 0
A8: =A7+1 -> 46117 | B8: =IFERROR(VLOOKUP(A8, Feiertage!$B:$C, 2, 0), IF(OR(WEEKDAY(A8,2)=6, WEEKDAY(A8,2)=7), Feiertage!$C$23, "")) -> * * * * * * * * Wochenende * * * * * * * * * * * * * * * * * * * * * * * * * * * * * * * * * * * * * * * * * * * * * * * * | R8: =IF(OR(WEEKDAY(A8,2)=6,WEEKDAY(A8,2)=7),0,IFERROR(IF(VLOOKUP(A8,Feiertage!$B:$D,3,0)="ja",0,Summen!$B$9),Summen!$B$9)) -> 0 | S8: =SUM(C8:Q8) -> 0 | T8: =S8-R8 -> 0 | U8: =U7+T8 -> 0 | X8: =V8+W8*Summen!$B$44 -> 0 | AG8: =(Z8-Y8)+(AB8-AA8)+(AD8-AC8)+(AF8-AE8) -> 0 | AH8: =HOUR(AG8) -> 0 | AI8: =MINUTE(AG8)/60 -> 0 | AJ8: =AH8+AI8 -> 0 | AL8: =SUM(C8:Q8)-AJ8 -> 0
A9: =A8+1 -> 46118 | B9: =IFERROR(VLOOKUP(A9, Feiertage!$B:$C, 2, 0), IF(OR(WEEKDAY(A9,2)=6, WEEKDAY(A9,2)=7), Feiertage!$C$23, "")) -> * * * * * * * * Ostermontag * * * * * * * * * * * * * * * * * * * * * * * * * * * * * * * * * * * * * * * * * * * * * * * * | R9: 0 | S9: =SUM(C9:Q9) -> 0 | T9: =S9-R9 -> 0 | U9: =U8+T9 -> 0 | X9: =V9+W9*Summen!$B$44 -> 0 | AG9: =(Z9-Y9)+(AB9-AA9)+(AD9-AC9)+(AF9-AE9) -> 0 | AH9: =HOUR(AG9) -> 0 | AI9: =MINUTE(AG9)/60 -> 0 | AJ9: =AH9+AI9 -> 0 | AL9: =SUM(C9:Q9)-AJ9 -> 0
A10: =A9+1 -> 46119 | B10: =IFERROR(VLOOKUP(A10, Feiertage!$B:$C, 2, 0), IF(OR(WEEKDAY(A10,2)=6, WEEKDAY(A10,2)=7), Feiertage!$C$23, "")) | R10: 0 | S10: =SUM(C10:Q10) -> 0 | T10: =S10-R10 -> 0 | U10: =U9+T10 -> 0 | X10: =V10+W10*Summen!$B$44 -> 0 | AG10: =(Z10-Y10)+(AB10-AA10)+(AD10-AC10)+(AF10-AE10) -> 0 | AH10: =HOUR(AG10) -> 0 | AI10: =MINUTE(AG10)/60 -> 0 | AJ10: =AH10+AI10 -> 0 | AL10: =SUM(C10:Q10)-AJ10 -> 0
A11: =A10+1 -> 46120 | B11: =IFERROR(VLOOKUP(A11, Feiertage!$B:$C, 2, 0), IF(OR(WEEKDAY(A11,2)=6, WEEKDAY(A11,2)=7), Feiertage!$C$23, "")) | R11: 0 | S11: =SUM(C11:Q11) -> 0 | T11: =S11-R11 -> 0 | U11: =U10+T11 -> 0 | X11: =V11+W11*Summen!$B$44 -> 0 | AG11: =(Z11-Y11)+(AB11-AA11)+(AD11-AC11)+(AF11-AE11) -> 0 | AH11: =HOUR(AG11) -> 0 | AI11: =MINUTE(AG11)/60 -> 0 | AJ11: =AH11+AI11 -> 0 | AL11: =SUM(C11:Q11)-AJ11 -> 0
A12: =A11+1 -> 46121 | B12: =IFERROR(VLOOKUP(A12, Feiertage!$B:$C, 2, 0), IF(OR(WEEKDAY(A12,2)=6, WEEKDAY(A12,2)=7), Feiertage!$C$23, "")) | R12: 0 | S12: =SUM(C12:Q12) -> 0 | T12: =S12-R12 -> 0 | U12: =U11+T12 -> 0 | X12: =V12+W12*Summen!$B$44 -> 0 | AG12: =(Z12-Y12)+(AB12-AA12)+(AD12-AC12)+(AF12-AE12) -> 0 | AH12: =HOUR(AG12) -> 0 | AI12: =MINUTE(AG12)/60 -> 0 | AJ12: =AH12+AI12 -> 0 | AL12: =SUM(C12:Q12)-AJ12 -> 0
A13: =A12+1 -> 46122 | B13: =IFERROR(VLOOKUP(A13, Feiertage!$B:$C, 2, 0), IF(OR(WEEKDAY(A13,2)=6, WEEKDAY(A13,2)=7), Feiertage!$C$23, "")) | R13: 0 | S13: =SUM(C13:Q13) -> 0 | T13: =S13-R13 -> 0 | U13: =U12+T13 -> 0 | X13: =V13+W13*Summen!$B$44 -> 0 | AG13: =(Z13-Y13)+(AB13-AA13)+(AD13-AC13)+(AF13-AE13) -> 0 | AH13: =HOUR(AG13) -> 0 | AI13: =MINUTE(AG13)/60 -> 0 | AJ13: =AH13+AI13 -> 0 | AL13: =SUM(C13:Q13)-AJ13 -> 0
A14: =A13+1 -> 46123 | B14: =IFERROR(VLOOKUP(A14, Feiertage!$B:$C, 2, 0), IF(OR(WEEKDAY(A14,2)=6, WEEKDAY(A14,2)=7), Feiertage!$C$23, "")) -> * * * * * * * * Wochenende * * * * * * * * * * * * * * * * * * * * * * * * * * * * * * * * * * * * * * * * * * * * * * * * | R14: =IF(OR(WEEKDAY(A14,2)=6,WEEKDAY(A14,2)=7),0,IFERROR(IF(VLOOKUP(A14,Feiertage!$B:$D,3,0)="ja",0,Summen!$B$9),Summen!$B$9)) -> 0 | S14: =SUM(C14:Q14) -> 0 | T14: =S14-R14 -> 0 | U14: =U13+T14 -> 0 | X14: =V14+W14*Summen!$B$44 -> 0 | AG14: =(Z14-Y14)+(AB14-AA14)+(AD14-AC14)+(AF14-AE14) -> 0 | AH14: =HOUR(AG14) -> 0 | AI14: =MINUTE(AG14)/60 -> 0 | AJ14: =AH14+AI14 -> 0 | AL14: =SUM(C14:Q14)-AJ14 -> 0
A15: =A14+1 -> 46124 | B15: =IFERROR(VLOOKUP(A15, Feiertage!$B:$C, 2, 0), IF(OR(WEEKDAY(A15,2)=6, WEEKDAY(A15,2)=7), Feiertage!$C$23, "")) -> * * * * * * * * Wochenende * * * * * * * * * * * * * * * * * * * * * * * * * * * * * * * * * * * * * * * * * * * * * * * * | R15: =IF(OR(WEEKDAY(A15,2)=6,WEEKDAY(A15,2)=7),0,IFERROR(IF(VLOOKUP(A15,Feiertage!$B:$D,3,0)="ja",0,Summen!$B$9),Summen!$B$9)) -> 0 | S15: =SUM(C15:Q15) -> 0 | T15: =S15-R15 -> 0 | U15: =U14+T15 -> 0 | X15: =V15+W15*Summen!$B$44 -> 0 | AG15: =(Z15-Y15)+(AB15-AA15)+(AD15-AC15)+(AF15-AE15) -> 0 | AH15: =HOUR(AG15) -> 0 | AI15: =MINUTE(AG15)/60 -> 0 | AJ15: =AH15+AI15 -> 0 | AL15: =SUM(C15:Q15)-AJ15 -> 0
A16: =A15+1 -> 46125 | B16: =IFERROR(VLOOKUP(A16, Feiertage!$B:$C, 2, 0), IF(OR(WEEKDAY(A16,2)=6, WEEKDAY(A16,2)=7), Feiertage!$C$23, "")) | R16: 0 | S16: =SUM(C16:Q16) -> 0 | T16: =S16-R16 -> 0 | U16: =U15+T16 -> 0 | X16: =V16+W16*Summen!$B$44 -> 0 | AG16: =(Z16-Y16)+(AB16-AA16)+(AD16-AC16)+(AF16-AE16) -> 0 | AH16: =HOUR(AG16) -> 0 | AI16: =MINUTE(AG16)/60 -> 0 | AJ16: =AH16+AI16 -> 0 | AL16: =SUM(C16:Q16)-AJ16 -> 0
A17: =A16+1 -> 46126 | B17: =IFERROR(VLOOKUP(A17, Feiertage!$B:$C, 2, 0), IF(OR(WEEKDAY(A17,2)=6, WEEKDAY(A17,2)=7), Feiertage!$C$23, "")) | R17: 0 | S17: =SUM(C17:Q17) -> 0 | T17: =S17-R17 -> 0 | U17: =U16+T17 -> 0 | X17: =V17+W17*Summen!$B$44 -> 0 | AG17: =(Z17-Y17)+(AB17-AA17)+(AD17-AC17)+(AF17-AE17) -> 0 | AH17: =HOUR(AG17) -> 0 | AI17: =MINUTE(AG17)/60 -> 0 | AJ17: =AH17+AI17 -> 0 | AL17: =SUM(C17:Q17)-AJ17 -> 0
A18: =A17+1 -> 46127 | B18: =IFERROR(VLOOKUP(A18, Feiertage!$B:$C, 2, 0), IF(OR(WEEKDAY(A18,2)=6, WEEKDAY(A18,2)=7), Feiertage!$C$23, "")) | R18: 0 | S18: =SUM(C18:Q18) -> 0 | T18: =S18-R18 -> 0 | U18: =U17+T18 -> 0 | X18: =V18+W18*Summen!$B$44 -> 0 | AG18: =(Z18-Y18)+(AB18-AA18)+(AD18-AC18)+(AF18-AE18) -> 0 | AH18: =HOUR(AG18) -> 0 | AI18: =MINUTE(AG18)/60 -> 0 | AJ18: =AH18+AI18 -> 0 | AL18: =SUM(C18:Q18)-AJ18 -> 0
A19: =A18+1 -> 46128 | B19: =IFERROR(VLOOKUP(A19, Feiertage!$B:$C, 2, 0), IF(OR(WEEKDAY(A19,2)=6, WEEKDAY(A19,2)=7), Feiertage!$C$23, "")) | R19: 0 | S19: =SUM(C19:Q19) -> 0 | T19: =S19-R19 -> 0 | U19: =U18+T19 -> 0 | X19: =V19+W19*Summen!$B$44 -> 0 | AG19: =(Z19-Y19)+(AB19-AA19)+(AD19-AC19)+(AF19-AE19) -> 0 | AH19: =HOUR(AG19) -> 0 | AI19: =MINUTE(AG19)/60 -> 0 | AJ19: =AH19+AI19 -> 0 | AL19: =SUM(C19:Q19)-AJ19 -> 0
A20: =A19+1 -> 46129 | B20: =IFERROR(VLOOKUP(A20, Feiertage!$B:$C, 2, 0), IF(OR(WEEKDAY(A20,2)=6, WEEKDAY(A20,2)=7), Feiertage!$C$23, "")) | R20: 0 | S20: =SUM(C20:Q20) -> 0 | T20: =S20-R20 -> 0 | U20: =U19+T20 -> 0 | X20: =V20+W20*Summen!$B$44 -> 0 | AG20: =(Z20-Y20)+(AB20-AA20)+(AD20-AC20)+(AF20-AE20) -> 0 | AH20: =HOUR(AG20) -> 0 | AI20: =MINUTE(AG20)/60 -> 0 | AJ20: =AH20+AI20 -> 0 | AL20: =SUM(C20:Q20)-AJ20 -> 0
A21: =A20+1 -> 46130 | B21: =IFERROR(VLOOKUP(A21, Feiertage!$B:$C, 2, 0), IF(OR(WEEKDAY(A21,2)=6, WEEKDAY(A21,2)=7), Feiertage!$C$23, "")) -> * * * * * * * * Wochenende * * * * * * * * * * * * * * * * * * * * * * * * * * * * * * * * * * * * * * * * * * * * * * * * | R21: =IF(OR(WEEKDAY(A21,2)=6,WEEKDAY(A21,2)=7),0,IFERROR(IF(VLOOKUP(A21,Feiertage!$B:$D,3,0)="ja",0,Summen!$B$9),Summen!$B$9)) -> 0 | S21: =SUM(C21:Q21) -> 0 | T21: =S21-R21 -> 0 | U21: =U20+T21 -> 0 | X21: =V21+W21*Summen!$B$44 -> 0 | AG21: =(Z21-Y21)+(AB21-AA21)+(AD21-AC21)+(AF21-AE21) -> 0 | AH21: =HOUR(AG21) -> 0 | AI21: =MINUTE(AG21)/60 -> 0 | AJ21: =AH21+AI21 -> 0 | AL21: =SUM(C21:Q21)-AJ21 -> 0
A22: =A21+1 -> 46131 | B22: =IFERROR(VLOOKUP(A22, Feiertage!$B:$C, 2, 0), IF(OR(WEEKDAY(A22,2)=6, WEEKDAY(A22,2)=7), Feiertage!$C$23, "")) -> * * * * * * * * Wochenende * * * * * * * * * * * * * * * * * * * * * * * * * * * * * * * * * * * * * * * * * * * * * * * * | R22: =IF(OR(WEEKDAY(A22,2)=6,WEEKDAY(A22,2)=7),0,IFERROR(IF(VLOOKUP(A22,Feiertage!$B:$D,3,0)="ja",0,Summen!$B$9),Summen!$B$9)) -> 0 | S22: =SUM(C22:Q22) -> 0 | T22: =S22-R22 -> 0 | U22: =U21+T22 -> 0 | X22: =V22+W22*Summen!$B$44 -> 0 | AG22: =(Z22-Y22)+(AB22-AA22)+(AD22-AC22)+(AF22-AE22) -> 0 | AH22: =HOUR(AG22) -> 0 | AI22: =MINUTE(AG22)/60 -> 0 | AJ22: =AH22+AI22 -> 0 | AL22: =SUM(C22:Q22)-AJ22 -> 0
A23: =A22+1 -> 46132 | B23: =IFERROR(VLOOKUP(A23, Feiertage!$B:$C, 2, 0), IF(OR(WEEKDAY(A23,2)=6, WEEKDAY(A23,2)=7), Feiertage!$C$23, "")) | R23: 0 | S23: =SUM(C23:Q23) -> 0 | T23: =S23-R23 -> 0 | U23: =U22+T23 -> 0 | X23: =V23+W23*Summen!$B$44 -> 0 | AG23: =(Z23-Y23)+(AB23-AA23)+(AD23-AC23)+(AF23-AE23) -> 0 | AH23: =HOUR(AG23) -> 0 | AI23: =MINUTE(AG23)/60 -> 0 | AJ23: =AH23+AI23 -> 0 | AL23: =SUM(C23:Q23)-AJ23 -> 0
A24: =A23+1 -> 46133 | B24: =IFERROR(VLOOKUP(A24, Feiertage!$B:$C, 2, 0), IF(OR(WEEKDAY(A24,2)=6, WEEKDAY(A24,2)=7), Feiertage!$C$23, "")) | R24: 0 | S24: =SUM(C24:Q24) -> 0 | T24: =S24-R24 -> 0 | U24: =U23+T24 -> 0 | X24: =V24+W24*Summen!$B$44 -> 0 | AG24: =(Z24-Y24)+(AB24-AA24)+(AD24-AC24)+(AF24-AE24) -> 0 | AH24: =HOUR(AG24) -> 0 | AI24: =MINUTE(AG24)/60 -> 0 | AJ24: =AH24+AI24 -> 0 | AL24: =SUM(C24:Q24)-AJ24 -> 0
A25: =A24+1 -> 46134 | B25: =IFERROR(VLOOKUP(A25, Feiertage!$B:$C, 2, 0), IF(OR(WEEKDAY(A25,2)=6, WEEKDAY(A25,2)=7), Feiertage!$C$23, "")) | R25: 0 | S25: =SUM(C25:Q25) -> 0 | T25: =S25-R25 -> 0 | U25: =U24+T25 -> 0 | X25: =V25+W25*Summen!$B$44 -> 0 | AG25: =(Z25-Y25)+(AB25-AA25)+(AD25-AC25)+(AF25-AE25) -> 0 | AH25: =HOUR(AG25) -> 0 | AI25: =MINUTE(AG25)/60 -> 0 | AJ25: =AH25+AI25 -> 0 | AL25: =SUM(C25:Q25)-AJ25 -> 0
